Workbook

Sheet Verlofoverzicht
B1: Urenregistratie
B2: Naam : | D2: Maickel | F2: Personeelsnr : | K2: Contracturen : | M2: 38 | N2: Jaar : | O2: 2025 | P2: Locatie: | Q2: SCHIJNDEL
B4: =_xlfn.CONCAT("Verlofuren ",O2-1) -> Verlofuren 2024 | J4: Bedrijfssluiting: | Q4: Van: | R4: Tot:
B5: Saldo vorig jaar: | E5: 40 | G5: uur | J5: Nieuwjaar | M5: 14.5 | O5: uur | Q5: week 1
J6: Dag na hemelvaart: | M6: 6 | O6: uur | Q6: 45807
B7: =_xlfn.CONCAT("Verlofuren ",O2) -> Verlofuren 2025 | J7: Bouwvak: | M7: 120 | O7: uur | Q7: 45859 | R7: 45877
B8: Verlof komend jaar: | E8: 200 | G8: uur | J8: Kerstvakantie: | O8: uur
B9: ADV dagen: | E9: 104 | G9: uur | J9: Totaal bedrijfssluiting: | M9: =SUM(M5:N8) -> 140.5 | O9: uur
B10: Senioren dagen: | E10: 0 | G10: uur
B11: Totaal verlof komend jaar: | E11: =SUM(E8:F10) -> 304 | G11: uur | J11: =_xlfn.CONCAT("Totaal vrije verlofuren ",O2) -> Totaal vrije verlofuren 2025 | M11: =E11-M9 -> 163.5 | O11: uur
B13: Aangevraagd verlof:
C14: Maand: | E14: Uren: | H14: Omschrijving: | M14: Van: | O14: Tot:
B15: 1 | C15: Januari | G15: =IF(E15="","","uur")
B16: 2 | C16: Februari | G16: =IF(E16="","","uur")
B17: 3 | C17: Maart | E17: 31.25 | G17: =IF(E17="","","uur") -> uur
B18: 4 | C18: April | E18: 14.5 | G18: =IF(E18="","","uur") -> uur | H18: 22-4 en 25-4
B19: 5 | C19: Mei | E19: 9.25 | G19: =IF(E19="","","uur") -> uur | H19: 6-5, 7-5, 12-5 en 16-5
B20: 6 | C20: Juni | E20: 34.5 | G20: =IF(E20="","","uur") -> uur | H20: 2-6, 4-6, 18-6, 19-6, 20-6, 23-6 en 24-6
B21: 7 | C21: Juli | E21: 13 | G21: =IF(E21="","","uur") -> uur | H21: 3-7 en 4-7
B22: 8 | C22: Augustus | E22: 12.5 | G22: =IF(E22="","","uur") -> uur
B23: 9 | C23: September | E23: 6 | G23: =IF(E23="","","uur") -> uur | M23: 45905 | O23: 45905
B24: 10 | C24: Oktober | E24: 6 | G24: =IF(E24="","","uur") -> uur | M24: 45933 | O24: 45933
B25: 11 | C25: November | G25: =IF(E25="","","uur")
B26: 12 | C26: December | E26: 51 | G26: =IF(E26="","","uur") -> uur | H26: 22-12 23-12 24-12 29-12 30-12 31-12
B27: Totaal aangevraagd verlof | E27: =SUM(E15:F26) -> 178
B29: =_xlfn.CONCAT("Beschikbare verlofuren ",O2-1) -> Beschikbare verlofuren 2024 | E29: {=_xlfn.IFS(Afspraken!J3>DATE(O2,6,30),0,Afspraken!J12<0.1,0,Afspraken!J12>0,Afspraken!J12)} -> 0 | G29: uren | H29: =_xlfn.CONCAT("Let op! Uren van ",O2-1," dienen voor 1 juli opgenomen te worden (voor vragen kun je terecht bij je leidinggevende") -> Let op! Uren van 2024 dienen voor 1 juli opgenomen te worden (voor vragen kun je terecht bij je leidinggevende
B30: =_xlfn.CONCAT("Beschikbare verlofuren ",O2) -> Beschikbare verlofuren 2025 | E30: =Afspraken!J22 -> 25.5 | G30: uren
B32: Verlof uren verloop: | K32: Werkelijk Vrij te besteden verlof | R32: Ziek:
B33: Maand | D33: Contract | E33: Bedrijfssluiting | G33: Gevraagd verlof | I33: Te werken | K33: # Te laat | L33: Correctie | M33: Gewerkt | N33: =_xlfn.CONCAT("Uren open (",O2-1," & ",O2,")") -> Uren open (2024 & 2025) | R33: =SUM('Periode 1'!F42,'Periode 2'!F42,'Periode 3'!F42,'Periode 4'!F42,'Periode 5'!F42,'Periode 6'!F42,'Periode 7'!F42,'Periode 8'!F42,'Periode 9'!F42,'Periode 10'!F42,'Periode 11'!F42,'Periode 12'!F42) -> 45.75
B34: Januari | D34: ='Periode 1'!$C$42 -> 183 | E34: 14.5 | G34: =SUMIF($C$15:$D$26,B34,$E$15:$F$26) -> 0 | I34: =D34-E34-G34 -> 168.5 | K34: ='Periode 1'!$D$42 -> 0 | L34: =IF(Afspraken!B28="Ja",Afspraken!U28,0) -> 0 | M34: ='Periode 1'!$E$42+'Periode 1'!$F$42+'Periode 1'!$H$42+L34 -> 168.5 | N34: =IF(M34<20,"",SUM(E29:F30)+(M34-I34)) -> 25.5
B35: Februari | D35: ='Periode 2'!$C$42 -> 160 | G35: =SUMIF($C$15:$D$26,B35,$E$15:$F$26) -> 0 | I35: =D35-E35-G35 -> 160 | K35: ='Periode 2'!$D$42 -> 0 | L35: =IF(Afspraken!B29="Ja",Afspraken!U29,0) -> 0 | M35: ='Periode 2'!$E$42+'Periode 2'!$F$42+'Periode 2'!$H$42+L35 -> 145.5 | N35: =IF(M35<20,"",IF(N34="",SUM($E$29:$F$30)+(M35-I35),N34+(M35-I35))) -> 11
B36: Maart | D36: ='Periode 3'!$C$42 -> 168.5 | G36: =SUMIF($C$15:$D$26,B36,$E$15:$F$26) -> 31.25 | I36: =D36-E36-G36 -> 137.25 | K36: ='Periode 3'!$D$42 -> 7 | L36: =IF(Afspraken!B30="Ja",Afspraken!U30,0) -> 0 | M36: ='Periode 3'!$E$42+'Periode 3'!$F$42+'Periode 3'!$H$42+L36 -> 137.25 | N36: =IF(M36<20,"",IF(N35="",SUM($E$29:$F$30)+(M36-I36),N35+(M36-I36))) -> 11
B37: April | D37: ='Periode 4'!$C$42 -> 177 | G37: =SUMIF($C$15:$D$26,B37,$E$15:$F$26) -> 14.5 | I37: =D37-E37-G37 -> 162.5 | K37: ='Periode 4'!$D$42 -> 0 | L37: =IF(Afspraken!B31="Ja",Afspraken!U31,0) -> 0 | M37: ='Periode 4'!$E$42+'Periode 4'!$F$42+'Periode 4'!$H$42+L37 -> 162.75 | N37: =IF(M37<20,"",IF(N36="",SUM($E$29:$F$30)+(M37-I37),N36+(M37-I37))) -> 11.25
B38: Mei | D38: ='Periode 5'!$C$42 -> 174.5 | E38: =M6 -> 6 | G38: =SUMIF($C$15:$D$26,B38,$E$15:$F$26) -> 9.25 | I38: =D38-E38-G38 -> 159.25 | K38: ='Periode 5'!$D$42 -> 0 | L38: =IF(Afspraken!B32="Ja",Afspraken!U32,0) -> 0 | M38: ='Periode 5'!$E$42+'Periode 5'!$F$42+'Periode 5'!$H$42+L38 -> 159.25 | N38: =IF(M38<20,"",IF(N37="",SUM($E$29:$F$30)+(M38-I38),N37+(M38-I38))) -> 11.25
B39: Juni | D39: ='Periode 6'!$C$42 -> 168.5 | G39: =SUMIF($C$15:$D$26,B39,$E$15:$F$26) -> 34.5 | I39: =D39-E39-G39 -> 134 | K39: ='Periode 6'!$D$42 -> 0 | L39: =IF(Afspraken!B33="Ja",Afspraken!U33,0) -> 0 | M39: ='Periode 6'!$E$42+'Periode 6'!$F$42+'Periode 6'!$H$42+L39 -> 134.25 | N39: =IF(M39<20,"",IF(N38="",SUM($E$29:$F$30)+(M39-I39),N38+(M39-I39))) -> 11.5
B40: Juli | D40: ='Periode 7'!$C$42 -> 185.5 | E40: 74 | G40: =SUMIF($C$15:$D$26,B40,$E$15:$F$26) -> 13 | I40: =D40-E40-G40 -> 98.5 | K40: ='Periode 7'!$D$42 -> 1 | L40: =IF(Afspraken!B34="Ja",Afspraken!U34,0) -> 0 | M40: ='Periode 7'!$E$42+'Periode 7'!$F$42+'Periode 7'!$H$42+L40 -> 99.5 | N40: =IF(M40<20,"",IF(N39="",SUM($E$29:$F$30)+(M40-I40),N39+(M40-I40))) -> 12.5
B41: Augustus | D41: ='Periode 8'!$C$42 -> 166 | E41: 46 | G41: =SUMIF($C$15:$D$26,B41,$E$15:$F$26) -> 12.5 | I41: =D41-E41-G41 -> 107.5 | K41: ='Periode 8'!$D$42 -> 2 | L41: =IF(Afspraken!B35="Ja",Afspraken!U35,0) -> 0 | M41: ='Periode 8'!$E$42+'Periode 8'!$F$42+'Periode 8'!$H$42+L41 -> 107.5 | N41: =IF(M41<20,"",IF(N40="",SUM($E$29:$F$30)+(M41-I41),N40+(M41-I41))) -> 12.5
B42: September | D42: ='Periode 9'!$C$42 -> 177 | G42: =SUMIF($C$15:$D$26,B42,$E$15:$F$26) -> 6 | I42: =D42-E42-G42 -> 171 | K42: ='Periode 9'!$D$42 -> 0 | L42: =IF(Afspraken!B36="Ja",Afspraken!U36,0) -> 0 | M42: ='Periode 9'!$E$42+'Periode 9'!$F$42+'Periode 9'!$H$42+L42 -> 171 | N42: =IF(M42<20,"",IF(N41="",SUM($E$29:$F$30)+(M42-I42),N41+(M42-I42))) -> 12.5
B43: Oktober | D43: ='Periode 10'!$C$42 -> 183 | G43: =SUMIF($C$15:$D$26,B43,$E$15:$F$26) -> 6 | I43: =D43-E43-G43 -> 177 | K43: ='Periode 10'!$D$42 -> 0 | L43: =IF(Afspraken!B37="Ja",Afspraken!U37,0) -> 0 | M43: ='Periode 10'!$E$42+'Periode 10'!$F$42+'Periode 10'!$H$42+L43 -> 17 | N43: =IF(M43<20,"",IF(N42="",SUM($E$29:$F$30)+(M43-I43),N42+(M43-I43)))
B44: November | D44: ='Periode 11'!$C$42 -> 160 | G44: =SUMIF($C$15:$D$26,B44,$E$15:$F$26) -> 0 | I44: =D44-E44-G44 -> 160 | K44: ='Periode 11'!$D$42 -> 0 | L44: =IF(Afspraken!B38="Ja",Afspraken!U38,0) -> 0 | M44: ='Periode 11'!$E$42+'Periode 11'!$F$42+'Periode 11'!$H$42+L44 -> 0 | N44: =IF(M44<20,"",IF(N43="",SUM($E$29:$F$30)+(M44-I44),N43+(M44-I44)))
...

Sheet Afspraken
A1: Afspraken van | B1: =IF(Verlofoverzicht!D2="","",Verlofoverzicht!D2) -> Maickel
I2: Berekening splitsing 2022 & 2023:
A3: Werkweek | B3: Start | C3: Eind | D3: Pauze 1 | E3: Pauze 2 | F3: Pauze 3 | G3: Totaal | I3: Vandaag: | J3: =TODAY() -> 45939
A4: Maandag | B4: 0.29166667 | C4: 0.6875 | D4: 0.010416667 | E4: 0.020833333 | F4: 0.010416667 | G4: =(C4-B4-D4-E4-F4)/(1/24) -> 8.5 | I4: Verlof vorig jaar:
A5: Dinsdag | B5: 0.29166667 | C5: 0.6875 | D5: 0.010416667 | E5: 0.020833333 | F5: 0.010416667 | G5: =(C5-B5-D5-E5-F5)/(1/24) -> 8.5 | I5: Maand | J5: Aangevraagd verlof
A6: Woensdag | B6: 0.29166667 | C6: 0.6875 | D6: 0.010416667 | E6: 0.020833333 | F6: 0.010416667 | G6: =(C6-B6-D6-E6-F6)/(1/24) -> 8.5 | I6: Januari | J6: =Verlofoverzicht!E15 -> 0
A7: Donderdag | B7: 0.29166667 | C7: 0.6875 | D7: 0.010416667 | E7: 0.020833333 | F7: 0.010416667 | G7: =(C7-B7-D7-E7-F7)/(1/24) -> 8.5 | I7: Februari | J7: =Verlofoverzicht!E16 -> 0
A8: Vrijdag | B8: 0.29166667 | C8: 0.57291667 | D8: 0.010416667 | E8: 0.020833333 | G8: =(C8-B8-D8-E8-F8)/(1/24) -> 6 | I8: Maart | J8: =Verlofoverzicht!E17 -> 31.25
A9: Totale werkweek | G9: =SUM(G4:G8) -> 40 | I9: April | J9: =Verlofoverzicht!E18 -> 14.5
A10: Indien een leidinggevende heeft gevraagd om over te werken, worden de overuren toegevoegd aan de vrij te besteden verlof uren van het op dat moment lopende jaar. | I10: Mei | J10: =Verlofoverzicht!E19 -> 9.25
I11: Juni | J11: =Verlofoverzicht!E20 -> 34.5
I12: Te besteden vorig jaar: | J12: =Verlofoverzicht!E5-SUM(J6:J11) -> -49.5
A14: Er mag maximaal 8 uur per jaar worden besteed aan bijzonder verlof, zoals tandarts en dokter. Indien een medewerker meer dan 8 uur besteed aan bijzonder verlof wordt dit aantal ingehouden van de vrij te besteden verlofuren van het op dat moment lopende jaar | I14: Verlof komend jaar:
I15: Juli | J15: =Verlofoverzicht!E21 -> 13
I16: Augustus | J16: =Verlofoverzicht!E22 -> 12.5
I17: September | J17: =Verlofoverzicht!E23 -> 6
A18: Aantal uren besteed aan bijzonder verlof: | E18: =SUM('Periode 1'!H42,'Periode 2'!H42,'Periode 3'!H42,'Periode 4'!H42,'Periode 5'!H42,'Periode 6'!H42,'Periode 7'!H42,'Periode 8'!H42,'Periode 9'!H42,'Periode 10'!H42,'Periode 11'!H42,'Periode 12'!H42) -> 0 | F18: Max: | G18: 8 | I18: Oktober | J18: =Verlofoverzicht!E24 -> 6
I19: November | J19: =Verlofoverzicht!E25 -> 0
A20: Indien een medewerker 2x in een maand te laat is geweest krijgt de medewerker een brief, met de consequenties voor de eerst volgende keer dat deze medewerker weer te laat is. In dat geval zullen er verlofuren van het op dat moment lopende jaar worden ingehouden. | I20: December | J20: =Verlofoverzicht!E26 -> 51
I21: Correctie Bijzonder verlof | J21: =IF(E18>G18,E18-G18,0) -> 0
I22: Te besteden komend jaar: | J22: =IF(J12>0,Verlofoverzicht!M11-SUM(J15:J21),Verlofoverzicht!M11-SUM(J15:J21)+J12) -> 25.5
A24: Aantal uur inhouden van verlof:
A25: Startpunt: | B25: -0.5 | D25: Per keer: | E25: 2 | F25: x zo veel (tot max 8 uur)
I26: Berekening Correctie Te Laat
A27: Maand | B27: Consequenties: | I27: Maand | J27: Aantal te laat: | K27: 1e x | L27: 2e x | M27: 3e x | N27: 4e x | O27: 5e x | P27: 6e x | Q27: 7e x | R27: 8e x | S27: 9e x | T27: 10e x | U27: Totaal correctie:
A28: Januari | B28: Nee | I28: Januari | J28: =Verlofoverzicht!K34 -> 0 | K28: =IF(J28>0,$B$25,0) -> 0 | L28: =IF($J28>1,K28*$E$25,0) -> 0 | M28: =IF($J28>2,L28*$E$25,0) -> 0 | N28: =IF($J28>3,M28*$E$25,0) -> 0 | O28: =IF($J28>4,N28*$E$25,0) -> 0 | P28: =IF($J28>5,O28,0) -> 0 | Q28: =IF($J28>6,P28,0) -> 0 | R28: =IF($J28>7,Q28,0) -> 0 | S28: =IF($J28>8,R28,0) -> 0 | T28: =IF($J28>9,S28,0) -> 0 | U28: =SUM(K28:T28) -> 0
A29: Februari | B29: Nee | I29: Februari | J29: =Verlofoverzicht!K35 -> 0 | K29: =IF(J29>0,$B$25,0) -> 0 | L29: =IF($J29>1,K29*$E$25,0) -> 0 | M29: =IF($J29>2,L29*$E$25,0) -> 0 | N29: =IF($J29>3,M29*$E$25,0) -> 0 | O29: =IF($J29>4,N29*$E$25,0) -> 0 | P29: =IF($J29>5,O29,0) -> 0 | Q29: =IF($J29>6,P29,0) -> 0 | R29: =IF($J29>7,Q29,0) -> 0 | S29: =IF($J29>8,R29,0) -> 0 | T29: =IF($J29>9,S29,0) -> 0 | U29: =SUM(K29:T29) -> 0
A30: Maart | B30: Nee | I30: Maart | J30: =Verlofoverzicht!K36 -> 7 | K30: =IF(J30>0,$B$25,0) -> -0.5 | L30: =IF($J30>1,K30*$E$25,0) -> -1 | M30: =IF($J30>2,L30*$E$25,0) -> -2 | N30: =IF($J30>3,M30*$E$25,0) -> -4 | O30: =IF($J30>4,N30*$E$25,0) -> -8 | P30: =IF($J30>5,O30,0) -> -8 | Q30: =IF($J30>6,P30,0) -> -8 | R30: =IF($J30>7,Q30,0) -> 0 | S30: =IF($J30>8,R30,0) -> 0 | T30: =IF($J30>9,S30,0) -> 0 | U30: =SUM(K30:T30) -> -31.5
A31: April | B31: Nee | I31: April | J31: =Verlofoverzicht!K37 -> 0 | K31: =IF(J31>0,$B$25,0) -> 0 | L31: =IF($J31>1,K31*$E$25,0) -> 0 | M31: =IF($J31>2,L31*$E$25,0) -> 0 | N31: =IF($J31>3,M31*$E$25,0) -> 0 | O31: =IF($J31>4,N31*$E$25,0) -> 0 | P31: =IF($J31>5,O31,0) -> 0 | Q31: =IF($J31>6,P31,0) -> 0 | R31: =IF($J31>7,Q31,0) -> 0 | S31: =IF($J31>8,R31,0) -> 0 | T31: =IF($J31>9,S31,0) -> 0 | U31: =SUM(K31:T31) -> 0
A32: Mei | B32: Nee | I32: Mei | J32: =Verlofoverzicht!K38 -> 0 | K32: =IF(J32>0,$B$25,0) -> 0 | L32: =IF($J32>1,K32*$E$25,0) -> 0 | M32: =IF($J32>2,L32*$E$25,0) -> 0 | N32: =IF($J32>3,M32*$E$25,0) -> 0 | O32: =IF($J32>4,N32*$E$25,0) -> 0 | P32: =IF($J32>5,O32,0) -> 0 | Q32: =IF($J32>6,P32,0) -> 0 | R32: =IF($J32>7,Q32,0) -> 0 | S32: =IF($J32>8,R32,0) -> 0 | T32: =IF($J32>9,S32,0) -> 0 | U32: =SUM(K32:T32) -> 0
A33: Juni | B33: Nee | I33: Juni | J33: =Verlofoverzicht!K39 -> 0 | K33: =IF(J33>0,$B$25,0) -> 0 | L33: =IF($J33>1,K33*$E$25,0) -> 0 | M33: =IF($J33>2,L33*$E$25,0) -> 0 | N33: =IF($J33>3,M33*$E$25,0) -> 0 | O33: =IF($J33>4,N33*$E$25,0) -> 0 | P33: =IF($J33>5,O33,0) -> 0 | Q33: =IF($J33>6,P33,0) -> 0 | R33: =IF($J33>7,Q33,0) -> 0 | S33: =IF($J33>8,R33,0) -> 0 | T33: =IF($J33>9,S33,0) -> 0 | U33: =SUM(K33:T33) -> 0
A34: Juli | B34: Nee | I34: Juli | J34: =Verlofoverzicht!K40 -> 1 | K34: =IF(J34>0,$B$25,0) -> -0.5 | L34: =IF($J34>1,K34*$E$25,0) -> 0 | M34: =IF($J34>2,L34*$E$25,0) -> 0 | N34: =IF($J34>3,M34*$E$25,0) -> 0 | O34: =IF($J34>4,N34*$E$25,0) -> 0 | P34: =IF($J34>5,O34,0) -> 0 | Q34: =IF($J34>6,P34,0) -> 0 | R34: =IF($J34>7,Q34,0) -> 0 | S34: =IF($J34>8,R34,0) -> 0 | T34: =IF($J34>9,S34,0) -> 0 | U34: =SUM(K34:T34) -> -0.5
A35: Augustus | B35: Nee | I35: Augustus | J35: =Verlofoverzicht!K41 -> 2 | K35: =IF(J35>0,$B$25,0) -> -0.5 | L35: =IF($J35>1,K35*$E$25,0) -> -1 | M35: =IF($J35>2,L35*$E$25,0) -> 0 | N35: =IF($J35>3,M35*$E$25,0) -> 0 | O35: =IF($J35>4,N35*$E$25,0) -> 0 | P35: =IF($J35>5,O35,0) -> 0 | Q35: =IF($J35>6,P35,0) -> 0 | R35: =IF($J35>7,Q35,0) -> 0 | S35: =IF($J35>8,R35,0) -> 0 | T35: =IF($J35>9,S35,0) -> 0 | U35: =SUM(K35:T35) -> -1.5
A36: September | B36: Nee | I36: September | J36: =Verlofoverzicht!K42 -> 0 | K36: =IF(J36>0,$B$25,0) -> 0 | L36: =IF($J36>1,K36*$E$25,0) -> 0 | M36: =IF($J36>2,L36*$E$25,0) -> 0 | N36: =IF($J36>3,M36*$E$25,0) -> 0 | O36: =IF($J36>4,N36*$E$25,0) -> 0 | P36: =IF($J36>5,O36,0) -> 0 | Q36: =IF($J36>6,P36,0) -> 0 | R36: =IF($J36>7,Q36,0) -> 0 | S36: =IF($J36>8,R36,0) -> 0 | T36: =IF($J36>9,S36,0) -> 0 | U36: =SUM(K36:T36) -> 0
A37: Oktober | B37: Nee | I37: Oktober | J37: =Verlofoverzicht!K43 -> 0 | K37: =IF(J37>0,$B$25,0) -> 0 | L37: =IF($J37>1,K37*$E$25,0) -> 0 | M37: =IF($J37>2,L37*$E$25,0) -> 0 | N37: =IF($J37>3,M37*$E$25,0) -> 0 | O37: =IF($J37>4,N37*$E$25,0) -> 0 | P37: =IF($J37>5,O37,0) -> 0 | Q37: =IF($J37>6,P37,0) -> 0 | R37: =IF($J37>7,Q37,0) -> 0 | S37: =IF($J37>8,R37,0) -> 0 | T37: =IF($J37>9,S37,0) -> 0 | U37: =SUM(K37:T37) -> 0
A38: November | B38: Nee | I38: November | J38: =Verlofoverzicht!K44 -> 0 | K38: =IF(J38>0,$B$25,0) -> 0 | L38: =IF($J38>1,K38*$E$25,0) -> 0 | M38: =IF($J38>2,L38*$E$25,0) -> 0 | N38: =IF($J38>3,M38*$E$25,0) -> 0 | O38: =IF($J38>4,N38*$E$25,0) -> 0 | P38: =IF($J38>5,O38,0) -> 0 | Q38: =IF($J38>6,P38,0) -> 0 | R38: =IF($J38>7,Q38,0) -> 0 | S38: =IF($J38>8,R38,0) -> 0 | T38: =IF($J38>9,S38,0) -> 0 | U38: =SUM(K38:T38) -> 0
A39: December | B39: Nee | I39: December | J39: =Verlofoverzicht!K45 -> 0 | K39: =IF(J39>0,$B$25,0) -> 0 | L39: =IF($J39>1,K39*$E$25,0) -> 0 | M39: =IF($J39>2,L39*$E$25,0) -> 0 | N39: =IF($J39>3,M39*$E$25,0) -> 0 | O39: =IF($J39>4,N39*$E$25,0) -> 0 | P39: =IF($J39>5,O39,0) -> 0 | Q39: =IF($J39>6,P39,0) -> 0 | R39: =IF($J39>7,Q39,0) -> 0 | S39: =IF($J39>8,R39,0) -> 0 | T39: =IF($J39>9,S39,0) -> 0 | U39: =SUM(K39:T39) -> 0
A41: Uren van het voorgaande jaar moeten voor 1 juli worden opgenomen. Indien deze niet vóór 1 juli zijn opgenomen worden deze uren kwijtgescholden. Indien het een erg groot aantal betreft wordt er een passende regeling getroffen en kan er contact worden gezocht met de leidinggevende.
A47: Indien een medewerker langdurig ziek is, bouwt deze medewerker geen ADV-dagen op
A50: Extra gemaakte afspraken:
...

Sheet Periode 1
B2: Urenregistratie
B4: Naam : | C4: =IF(Verlofoverzicht!D2="","",Verlofoverzicht!D2) -> Maickel | D4: Periode : | E4: 1 | F4: Jaar : | G4: =Verlofoverzicht!$O$2 -> 2025
B6: Contracturen : | C6: 38 | D6: Lokatie : | E6: SCHIJNDEL
B8: Datum | C8: Contracturen | D8: te laat | E8: Gewerkt | F8: Ziek | G8: Verlof | H8: Tandarts / Dokter
D9: ALLEEN 'x' invullen
B10: =DATE(G4,E4,1) -> 45658 | C10: =IFERROR(VLOOKUP(TEXT(WEEKDAY(B10),"dddd"),Afspraken!$A$4:$G$8,7,FALSE),"") -> 8.5 | E10: 8.5
B11: =IF(MONTH(B10+1)<>$E$4,"",B10+1) -> 45659 | C11: =IFERROR(VLOOKUP(TEXT(WEEKDAY(B11),"dddd"),Afspraken!$A$4:$G$8,7,FALSE),"") -> 8.5 | G11: 8.5
B12: =IF(MONTH(B11+1)<>$E$4,"",B11+1) -> 45660 | C12: =IFERROR(VLOOKUP(TEXT(WEEKDAY(B12),"dddd"),Afspraken!$A$4:$G$8,7,FALSE),"") -> 6 | G12: 6
B13: =IF(MONTH(B12+1)<>$E$4,"",B12+1) -> 45661 | C13: =IFERROR(VLOOKUP(TEXT(WEEKDAY(B13),"dddd"),Afspraken!$A$4:$G$8,7,FALSE),"")
B14: =IF(MONTH(B13+1)<>$E$4,"",B13+1) -> 45662 | C14: =IFERROR(VLOOKUP(TEXT(WEEKDAY(B14),"dddd"),Afspraken!$A$4:$G$8,7,FALSE),"")
B15: =IF(MONTH(B14+1)<>$E$4,"",B14+1) -> 45663 | C15: =IFERROR(VLOOKUP(TEXT(WEEKDAY(B15),"dddd"),Afspraken!$A$4:$G$8,7,FALSE),"") -> 8.5 | E15: 7.5 | F15: 1
B16: =IF(MONTH(B15+1)<>$E$4,"",B15+1) -> 45664 | C16: =IFERROR(VLOOKUP(TEXT(WEEKDAY(B16),"dddd"),Afspraken!$A$4:$G$8,7,FALSE),"") -> 8.5 | E16: 8.5
B17: =IF(MONTH(B16+1)<>$E$4,"",B16+1) -> 45665 | C17: =IFERROR(VLOOKUP(TEXT(WEEKDAY(B17),"dddd"),Afspraken!$A$4:$G$8,7,FALSE),"") -> 8.5 | E17: 8.5
B18: =IF(MONTH(B17+1)<>$E$4,"",B17+1) -> 45666 | C18: =IFERROR(VLOOKUP(TEXT(WEEKDAY(B18),"dddd"),Afspraken!$A$4:$G$8,7,FALSE),"") -> 8.5 | E18: 4.75 | F18: 3.75
B19: =IF(MONTH(B18+1)<>$E$4,"",B18+1) -> 45667 | C19: =IFERROR(VLOOKUP(TEXT(WEEKDAY(B19),"dddd"),Afspraken!$A$4:$G$8,7,FALSE),"") -> 6 | E19: 5.5 | F19: 0.5
B20: =IF(MONTH(B19+1)<>$E$4,"",B19+1) -> 45668 | C20: =IFERROR(VLOOKUP(TEXT(WEEKDAY(B20),"dddd"),Afspraken!$A$4:$G$8,7,FALSE),"")
B21: =IF(MONTH(B20+1)<>$E$4,"",B20+1) -> 45669 | C21: =IFERROR(VLOOKUP(TEXT(WEEKDAY(B21),"dddd"),Afspraken!$A$4:$G$8,7,FALSE),"")
B22: =IF(MONTH(B21+1)<>$E$4,"",B21+1) -> 45670 | C22: =IFERROR(VLOOKUP(TEXT(WEEKDAY(B22),"dddd"),Afspraken!$A$4:$G$8,7,FALSE),"") -> 8.5 | E22: 4.75 | F22: 3.75
B23: =IF(MONTH(B22+1)<>$E$4,"",B22+1) -> 45671 | C23: =IFERROR(VLOOKUP(TEXT(WEEKDAY(B23),"dddd"),Afspraken!$A$4:$G$8,7,FALSE),"") -> 8.5 | E23: 8
B24: =IF(MONTH(B23+1)<>$E$4,"",B23+1) -> 45672 | C24: =IFERROR(VLOOKUP(TEXT(WEEKDAY(B24),"dddd"),Afspraken!$A$4:$G$8,7,FALSE),"") -> 8.5 | E24: 4.75 | F24: 1.75
B25: =IF(MONTH(B24+1)<>$E$4,"",B24+1) -> 45673 | C25: =IFERROR(VLOOKUP(TEXT(WEEKDAY(B25),"dddd"),Afspraken!$A$4:$G$8,7,FALSE),"") -> 8.5 | E25: 11
B26: =IF(MONTH(B25+1)<>$E$4,"",B25+1) -> 45674 | C26: =IFERROR(VLOOKUP(TEXT(WEEKDAY(B26),"dddd"),Afspraken!$A$4:$G$8,7,FALSE),"") -> 6 | E26: 6
B27: =IF(MONTH(B26+1)<>$E$4,"",B26+1) -> 45675 | C27: =IFERROR(VLOOKUP(TEXT(WEEKDAY(B27),"dddd"),Afspraken!$A$4:$G$8,7,FALSE),"")
B28: =IF(MONTH(B27+1)<>$E$4,"",B27+1) -> 45676 | C28: =IFERROR(VLOOKUP(TEXT(WEEKDAY(B28),"dddd"),Afspraken!$A$4:$G$8,7,FALSE),"")
B29: =IF(MONTH(B28+1)<>$E$4,"",B28+1) -> 45677 | C29: =IFERROR(VLOOKUP(TEXT(WEEKDAY(B29),"dddd"),Afspraken!$A$4:$G$8,7,FALSE),"") -> 8.5 | E29: 4.75 | F29: 3.75
B30: =IF(MONTH(B29+1)<>$E$4,"",B29+1) -> 45678 | C30: =IFERROR(VLOOKUP(TEXT(WEEKDAY(B30),"dddd"),Afspraken!$A$4:$G$8,7,FALSE),"") -> 8.5 | E30: 8
B31: =IF(MONTH(B30+1)<>$E$4,"",B30+1) -> 45679 | C31: =IFERROR(VLOOKUP(TEXT(WEEKDAY(B31),"dddd"),Afspraken!$A$4:$G$8,7,FALSE),"") -> 8.5 | E31: 8.5
B32: =IF(MONTH(B31+1)<>$E$4,"",B31+1) -> 45680 | C32: =IFERROR(VLOOKUP(TEXT(WEEKDAY(B32),"dddd"),Afspraken!$A$4:$G$8,7,FALSE),"") -> 8.5 | E32: 6.75 | F32: 1.5
B33: =IF(MONTH(B32+1)<>$E$4,"",B32+1) -> 45681 | C33: =IFERROR(VLOOKUP(TEXT(WEEKDAY(B33),"dddd"),Afspraken!$A$4:$G$8,7,FALSE),"") -> 6 | E33: 6.75
B34: =IF(MONTH(B33+1)<>$E$4,"",B33+1) -> 45682 | C34: =IFERROR(VLOOKUP(TEXT(WEEKDAY(B34),"dddd"),Afspraken!$A$4:$G$8,7,FALSE),"")
B35: =IF(MONTH(B34+1)<>$E$4,"",B34+1) -> 45683 | C35: =IFERROR(VLOOKUP(TEXT(WEEKDAY(B35),"dddd"),Afspraken!$A$4:$G$8,7,FALSE),"")
B36: =IF(MONTH(B35+1)<>$E$4,"",B35+1) -> 45684 | C36: =IFERROR(VLOOKUP(TEXT(WEEKDAY(B36),"dddd"),Afspraken!$A$4:$G$8,7,FALSE),"") -> 8.5 | E36: 6.75 | F36: 1.75
B37: =IF(MONTH(B36+1)<>$E$4,"",B36+1) -> 45685 | C37: =IFERROR(VLOOKUP(TEXT(WEEKDAY(B37),"dddd"),Afspraken!$A$4:$G$8,7,FALSE),"") -> 8.5 | E37: 8 | F37: 0.5
B38: =IF(MONTH(B37+1)<>$E$4,"",B37+1) -> 45686 | C38: =IFERROR(VLOOKUP(TEXT(WEEKDAY(B38),"dddd"),Afspraken!$A$4:$G$8,7,FALSE),"") -> 8.5 | E38: 8 | F38: 0.5
B39: =IF(MONTH(B37+2)<>$E$4,"",B37+2) -> 45687 | C39: =IFERROR(VLOOKUP(TEXT(WEEKDAY(B39),"dddd"),Afspraken!$A$4:$G$8,7,FALSE),"") -> 8.5 | E39: 8 | F39: 0.5
B40: =IF(MONTH(B37+3)<>$E$4,"",B37+3) -> 45688 | C40: =IFERROR(VLOOKUP(TEXT(WEEKDAY(B40),"dddd"),Afspraken!$A$4:$G$8,7,FALSE),"") -> 6 | E40: 5.5 | F40: 0.5
B42: Maand | C42: =SUM(C10:C40) -> 183 | D42: =SUM(D10:D40) -> 0 | E42: =SUM(E10:E40) -> 148.75 | F42: =SUM(F10:F40) -> 19.75 | G42: =SUM(G10:G40) -> 14.5 | H42: =SUM(H10:H40) -> 0

Sheet Periode 2
B2: Urenregistratie
B4: Naam : | C4: =IF(Verlofoverzicht!D2="","",Verlofoverzicht!D2) -> Maickel | D4: Periode : | E4: 2 | F4: Jaar : | G4: =Verlofoverzicht!$O$2 -> 2025
B6: Contracturen : | C6: 38 | D6: Lokatie : | E6: SCHIJNDEL
B8: Datum | C8: Contracturen | D8: te laat | E8: Gewerkt | F8: Ziek | G8: Verlof | H8: Tandarts / Dokter
D9: ALLEEN 'x' invullen
B10: =DATE(G4,E4,1) -> 45689 | C10: =IFERROR(VLOOKUP(TEXT(WEEKDAY(B10),"dddd"),Afspraken!$A$4:$G$8,7,FALSE),"")
B11: =IF(MONTH(B10+1)<>$E$4,"",B10+1) -> 45690 | C11: =IFERROR(VLOOKUP(TEXT(WEEKDAY(B11),"dddd"),Afspraken!$A$4:$G$8,7,FALSE),"")
B12: =IF(MONTH(B11+1)<>$E$4,"",B11+1) -> 45691 | C12: =IFERROR(VLOOKUP(TEXT(WEEKDAY(B12),"dddd"),Afspraken!$A$4:$G$8,7,FALSE),"") -> 8.5 | E12: 8 | F12: 0.5
B13: =IF(MONTH(B12+1)<>$E$4,"",B12+1) -> 45692 | C13: =IFERROR(VLOOKUP(TEXT(WEEKDAY(B13),"dddd"),Afspraken!$A$4:$G$8,7,FALSE),"") -> 8.5 | E13: 8 | F13: 0.5
B14: =IF(MONTH(B13+1)<>$E$4,"",B13+1) -> 45693 | C14: =IFERROR(VLOOKUP(TEXT(WEEKDAY(B14),"dddd"),Afspraken!$A$4:$G$8,7,FALSE),"") -> 8.5 | E14: 8 | F14: 0.5
B15: =IF(MONTH(B14+1)<>$E$4,"",B14+1) -> 45694 | C15: =IFERROR(VLOOKUP(TEXT(WEEKDAY(B15),"dddd"),Afspraken!$A$4:$G$8,7,FALSE),"") -> 8.5 | F15: 8.5
B16: =IF(MONTH(B15+1)<>$E$4,"",B15+1) -> 45695 | C16: =IFERROR(VLOOKUP(TEXT(WEEKDAY(B16),"dddd"),Afspraken!$A$4:$G$8,7,FALSE),"") -> 6 | F16: 6
B17: =IF(MONTH(B16+1)<>$E$4,"",B16+1) -> 45696 | C17: =IFERROR(VLOOKUP(TEXT(WEEKDAY(B17),"dddd"),Afspraken!$A$4:$G$8,7,FALSE),"")
B18: =IF(MONTH(B17+1)<>$E$4,"",B17+1) -> 45697 | C18: =IFERROR(VLOOKUP(TEXT(WEEKDAY(B18),"dddd"),Afspraken!$A$4:$G$8,7,FALSE),"")
B19: =IF(MONTH(B18+1)<>$E$4,"",B18+1) -> 45698 | C19: =IFERROR(VLOOKUP(TEXT(WEEKDAY(B19),"dddd"),Afspraken!$A$4:$G$8,7,FALSE),"") -> 8.5 | E19: 6.75 | F19: 1.75
B20: =IF(MONTH(B19+1)<>$E$4,"",B19+1) -> 45699 | C20: =IFERROR(VLOOKUP(TEXT(WEEKDAY(B20),"dddd"),Afspraken!$A$4:$G$8,7,FALSE),"") -> 8.5 | E20: 8 | F20: 0.5
B21: =IF(MONTH(B20+1)<>$E$4,"",B20+1) -> 45700 | C21: =IFERROR(VLOOKUP(TEXT(WEEKDAY(B21),"dddd"),Afspraken!$A$4:$G$8,7,FALSE),"") -> 8.5 | E21: 8.5
B22: =IF(MONTH(B21+1)<>$E$4,"",B21+1) -> 45701 | C22: =IFERROR(VLOOKUP(TEXT(WEEKDAY(B22),"dddd"),Afspraken!$A$4:$G$8,7,FALSE),"") -> 8.5 | E22: 8 | F22: 0.5
B23: =IF(MONTH(B22+1)<>$E$4,"",B22+1) -> 45702 | C23: =IFERROR(VLOOKUP(TEXT(WEEKDAY(B23),"dddd"),Afspraken!$A$4:$G$8,7,FALSE),"") -> 6 | E23: 6
B24: =IF(MONTH(B23+1)<>$E$4,"",B23+1) -> 45703 | C24: =IFERROR(VLOOKUP(TEXT(WEEKDAY(B24),"dddd"),Afspraken!$A$4:$G$8,7,FALSE),"")
B25: =IF(MONTH(B24+1)<>$E$4,"",B24+1) -> 45704 | C25: =IFERROR(VLOOKUP(TEXT(WEEKDAY(B25),"dddd"),Afspraken!$A$4:$G$8,7,FALSE),"")
B26: =IF(MONTH(B25+1)<>$E$4,"",B25+1) -> 45705 | C26: =IFERROR(VLOOKUP(TEXT(WEEKDAY(B26),"dddd"),Afspraken!$A$4:$G$8,7,FALSE),"") -> 8.5 | E26: 8 | F26: 0.5
B27: =IF(MONTH(B26+1)<>$E$4,"",B26+1) -> 45706 | C27: =IFERROR(VLOOKUP(TEXT(WEEKDAY(B27),"dddd"),Afspraken!$A$4:$G$8,7,FALSE),"") -> 8.5 | E27: 8 | F27: 0.5
B28: =IF(MONTH(B27+1)<>$E$4,"",B27+1) -> 45707 | C28: =IFERROR(VLOOKUP(TEXT(WEEKDAY(B28),"dddd"),Afspraken!$A$4:$G$8,7,FALSE),"") -> 8.5 | E28: 8 | F28: 0.5
B29: =IF(MONTH(B28+1)<>$E$4,"",B28+1) -> 45708 | C29: =IFERROR(VLOOKUP(TEXT(WEEKDAY(B29),"dddd"),Afspraken!$A$4:$G$8,7,FALSE),"") -> 8.5 | G29: 8.5
B30: =IF(MONTH(B29+1)<>$E$4,"",B29+1) -> 45709 | C30: =IFERROR(VLOOKUP(TEXT(WEEKDAY(B30),"dddd"),Afspraken!$A$4:$G$8,7,FALSE),"") -> 6 | G30: 6
B31: =IF(MONTH(B30+1)<>$E$4,"",B30+1) -> 45710 | C31: =IFERROR(VLOOKUP(TEXT(WEEKDAY(B31),"dddd"),Afspraken!$A$4:$G$8,7,FALSE),"")
B32: =IF(MONTH(B31+1)<>$E$4,"",B31+1) -> 45711 | C32: =IFERROR(VLOOKUP(TEXT(WEEKDAY(B32),"dddd"),Afspraken!$A$4:$G$8,7,FALSE),"")
B33: =IF(MONTH(B32+1)<>$E$4,"",B32+1) -> 45712 | C33: =IFERROR(VLOOKUP(TEXT(WEEKDAY(B33),"dddd"),Afspraken!$A$4:$G$8,7,FALSE),"") -> 8.5 | E33: 8 | F33: 0.5
B34: =IF(MONTH(B33+1)<>$E$4,"",B33+1) -> 45713 | C34: =IFERROR(VLOOKUP(TEXT(WEEKDAY(B34),"dddd"),Afspraken!$A$4:$G$8,7,FALSE),"") -> 8.5 | E34: 4.75 | F34: 3.75
B35: =IF(MONTH(B34+1)<>$E$4,"",B34+1) -> 45714 | C35: =IFERROR(VLOOKUP(TEXT(WEEKDAY(B35),"dddd"),Afspraken!$A$4:$G$8,7,FALSE),"") -> 8.5 | E35: 7.5 | F35: 1
B36: =IF(MONTH(B35+1)<>$E$4,"",B35+1) -> 45715 | C36: =IFERROR(VLOOKUP(TEXT(WEEKDAY(B36),"dddd"),Afspraken!$A$4:$G$8,7,FALSE),"") -> 8.5 | E36: 8 | F36: 0.5
B37: =IF(MONTH(B36+1)<>$E$4,"",B36+1) -> 45716 | C37: =IFERROR(VLOOKUP(TEXT(WEEKDAY(B37),"dddd"),Afspraken!$A$4:$G$8,7,FALSE),"") -> 6 | E37: 6
B38: =IF(MONTH(B37+1)<>$E$4,"",B37+1) | C38: =IFERROR(VLOOKUP(TEXT(WEEKDAY(B38),"dddd"),Afspraken!$A$4:$G$8,7,FALSE),"")
B39: =IF(MONTH(B37+2)<>$E$4,"",B37+2) | C39: =IFERROR(VLOOKUP(TEXT(WEEKDAY(B39),"dddd"),Afspraken!$A$4:$G$8,7,FALSE),"")
B40: =IF(MONTH(B37+3)<>$E$4,"",B37+3) | C40: =IFERROR(VLOOKUP(TEXT(WEEKDAY(B40),"dddd"),Afspraken!$A$4:$G$8,7,FALSE),"")
B42: Totaal | C42: =SUM(C10:C40) -> 160 | D42: =SUM(D10:D40) -> 0 | E42: =SUM(E10:E40) -> 119.5 | F42: =SUM(F10:F40) -> 26 | G42: =SUM(G10:G40) -> 14.5 | H42: =SUM(H10:H40) -> 0

Sheet Periode 3
B2: Urenregistratie
B4: Naam : | C4: =IF(Verlofoverzicht!D2="","",Verlofoverzicht!D2) -> Maickel | D4: Periode : | E4: 3 | F4: Jaar : | G4: =Verlofoverzicht!$O$2 -> 2025
B6: Contracturen : | C6: 38 | D6: Lokatie : | E6: SCHIJNDEL
B8: Datum | C8: Contracturen | D8: te laat | E8: Gewerkt | F8: Ziek | G8: Verlof | H8: Tandarts / Dokter
D9: ALLEEN 'x' invullen
B10: =DATE(G4,E4,1) -> 45717 | C10: =IFERROR(VLOOKUP(TEXT(WEEKDAY(B10),"dddd"),Afspraken!$A$4:$G$8,7,FALSE),"")
B11: =IF(MONTH(B10+1)<>$E$4,"",B10+1) -> 45718 | C11: =IFERROR(VLOOKUP(TEXT(WEEKDAY(B11),"dddd"),Afspraken!$A$4:$G$8,7,FALSE),"")
B12: =IF(MONTH(B11+1)<>$E$4,"",B11+1) -> 45719 | C12: =IFERROR(VLOOKUP(TEXT(WEEKDAY(B12),"dddd"),Afspraken!$A$4:$G$8,7,FALSE),"") -> 8.5 | D12: x | E12: 8.5
B13: =IF(MONTH(B12+1)<>$E$4,"",B12+1) -> 45720 | C13: =IFERROR(VLOOKUP(TEXT(WEEKDAY(B13),"dddd"),Afspraken!$A$4:$G$8,7,FALSE),"") -> 8.5 | E13: 8.5
B14: =IF(MONTH(B13+1)<>$E$4,"",B13+1) -> 45721 | C14: =IFERROR(VLOOKUP(TEXT(WEEKDAY(B14),"dddd"),Afspraken!$A$4:$G$8,7,FALSE),"") -> 8.5 | G14: 8.5
B15: =IF(MONTH(B14+1)<>$E$4,"",B14+1) -> 45722 | C15: =IFERROR(VLOOKUP(TEXT(WEEKDAY(B15),"dddd"),Afspraken!$A$4:$G$8,7,FALSE),"") -> 8.5 | G15: 8.5
B16: =IF(MONTH(B15+1)<>$E$4,"",B15+1) -> 45723 | C16: =IFERROR(VLOOKUP(TEXT(WEEKDAY(B16),"dddd"),Afspraken!$A$4:$G$8,7,FALSE),"") -> 6 | G16: 6
B17: =IF(MONTH(B16+1)<>$E$4,"",B16+1) -> 45724 | C17: =IFERROR(VLOOKUP(TEXT(WEEKDAY(B17),"dddd"),Afspraken!$A$4:$G$8,7,FALSE),"")
B18: =IF(MONTH(B17+1)<>$E$4,"",B17+1) -> 45725 | C18: =IFERROR(VLOOKUP(TEXT(WEEKDAY(B18),"dddd"),Afspraken!$A$4:$G$8,7,FALSE),"")
B19: =IF(MONTH(B18+1)<>$E$4,"",B18+1) -> 45726 | C19: =IFERROR(VLOOKUP(TEXT(WEEKDAY(B19),"dddd"),Afspraken!$A$4:$G$8,7,FALSE),"") -> 8.5 | D19: x | E19: 8.5
B20: =IF(MONTH(B19+1)<>$E$4,"",B19+1) -> 45727 | C20: =IFERROR(VLOOKUP(TEXT(WEEKDAY(B20),"dddd"),Afspraken!$A$4:$G$8,7,FALSE),"") -> 8.5 | E20: 8.5
B21: =IF(MONTH(B20+1)<>$E$4,"",B20+1) -> 45728 | C21: =IFERROR(VLOOKUP(TEXT(WEEKDAY(B21),"dddd"),Afspraken!$A$4:$G$8,7,FALSE),"") -> 8.5 | D21: x | E21: 8.5
B22: =IF(MONTH(B21+1)<>$E$4,"",B21+1) -> 45729 | C22: =IFERROR(VLOOKUP(TEXT(WEEKDAY(B22),"dddd"),Afspraken!$A$4:$G$8,7,FALSE),"") -> 8.5 | D22: x | E22: 8.5
B23: =IF(MONTH(B22+1)<>$E$4,"",B22+1) -> 45730 | C23: =IFERROR(VLOOKUP(TEXT(WEEKDAY(B23),"dddd"),Afspraken!$A$4:$G$8,7,FALSE),"") -> 6 | D23: x | E23: 6
B24: =IF(MONTH(B23+1)<>$E$4,"",B23+1) -> 45731 | C24: =IFERROR(VLOOKUP(TEXT(WEEKDAY(B24),"dddd"),Afspraken!$A$4:$G$8,7,FALSE),"")
B25: =IF(MONTH(B24+1)<>$E$4,"",B24+1) -> 45732 | C25: =IFERROR(VLOOKUP(TEXT(WEEKDAY(B25),"dddd"),Afspraken!$A$4:$G$8,7,FALSE),"")
B26: =IF(MONTH(B25+1)<>$E$4,"",B25+1) -> 45733 | C26: =IFERROR(VLOOKUP(TEXT(WEEKDAY(B26),"dddd"),Afspraken!$A$4:$G$8,7,FALSE),"") -> 8.5 | D26: x | E26: 8.5
B27: =IF(MONTH(B26+1)<>$E$4,"",B26+1) -> 45734 | C27: =IFERROR(VLOOKUP(TEXT(WEEKDAY(B27),"dddd"),Afspraken!$A$4:$G$8,7,FALSE),"") -> 8.5 | D27: x | E27: 8.5
B28: =IF(MONTH(B27+1)<>$E$4,"",B27+1) -> 45735 | C28: =IFERROR(VLOOKUP(TEXT(WEEKDAY(B28),"dddd"),Afspraken!$A$4:$G$8,7,FALSE),"") -> 8.5 | E28: 8.5
B29: =IF(MONTH(B28+1)<>$E$4,"",B28+1) -> 45736 | C29: =IFERROR(VLOOKUP(TEXT(WEEKDAY(B29),"dddd"),Afspraken!$A$4:$G$8,7,FALSE),"") -> 8.5 | E29: 5.5 | G29: 3
B30: =IF(MONTH(B29+1)<>$E$4,"",B29+1) -> 45737 | C30: =IFERROR(VLOOKUP(TEXT(WEEKDAY(B30),"dddd"),Afspraken!$A$4:$G$8,7,FALSE),"") -> 6 | E30: 6
B31: =IF(MONTH(B30+1)<>$E$4,"",B30+1) -> 45738 | C31: =IFERROR(VLOOKUP(TEXT(WEEKDAY(B31),"dddd"),Afspraken!$A$4:$G$8,7,FALSE),"")
B32: =IF(MONTH(B31+1)<>$E$4,"",B31+1) -> 45739 | C32: =IFERROR(VLOOKUP(TEXT(WEEKDAY(B32),"dddd"),Afspraken!$A$4:$G$8,7,FALSE),"")
B33: =IF(MONTH(B32+1)<>$E$4,"",B32+1) -> 45740 | C33: =IFERROR(VLOOKUP(TEXT(WEEKDAY(B33),"dddd"),Afspraken!$A$4:$G$8,7,FALSE),"") -> 8.5 | E33: 8.5
B34: =IF(MONTH(B33+1)<>$E$4,"",B33+1) -> 45741 | C34: =IFERROR(VLOOKUP(TEXT(WEEKDAY(B34),"dddd"),Afspraken!$A$4:$G$8,7,FALSE),"") -> 8.5 | E34: 8.5
B35: =IF(MONTH(B34+1)<>$E$4,"",B34+1) -> 45742 | C35: =IFERROR(VLOOKUP(TEXT(WEEKDAY(B35),"dddd"),Afspraken!$A$4:$G$8,7,FALSE),"") -> 8.5 | E35: 5.5 | G35: 3
B36: =IF(MONTH(B35+1)<>$E$4,"",B35+1) -> 45743 | C36: =IFERROR(VLOOKUP(TEXT(WEEKDAY(B36),"dddd"),Afspraken!$A$4:$G$8,7,FALSE),"") -> 8.5 | E36: 6.25 | G36: 2.25
B37: =IF(MONTH(B36+1)<>$E$4,"",B36+1) -> 45744 | C37: =IFERROR(VLOOKUP(TEXT(WEEKDAY(B37),"dddd"),Afspraken!$A$4:$G$8,7,FALSE),"") -> 6 | E37: 6
B38: =IF(MONTH(B37+1)<>$E$4,"",B37+1) -> 45745 | C38: =IFERROR(VLOOKUP(TEXT(WEEKDAY(B38),"dddd"),Afspraken!$A$4:$G$8,7,FALSE),"")
B39: =IF(MONTH(B37+2)<>$E$4,"",B37+2) -> 45746 | C39: =IFERROR(VLOOKUP(TEXT(WEEKDAY(B39),"dddd"),Afspraken!$A$4:$G$8,7,FALSE),"")
B40: =IF(MONTH(B37+3)<>$E$4,"",B37+3) -> 45747 | C40: =IFERROR(VLOOKUP(TEXT(WEEKDAY(B40),"dddd"),Afspraken!$A$4:$G$8,7,FALSE),"") -> 8.5 | E40: 8.5
B42: Totaal | C42: =SUM(C10:C40) -> 168.5 | D42: 7 | E42: =SUM(E10:E40) -> 137.25 | F42: =SUM(F10:F40) -> 0 | G42: =SUM(G10:G40) -> 31.25 | H42: =SUM(H10:H40) -> 0

Sheet Periode 4
B2: Urenregistratie
B4: Naam : | C4: =IF(Verlofoverzicht!D2="","",Verlofoverzicht!D2) -> Maickel | D4: Periode : | E4: 4 | F4: Jaar : | G4: =Verlofoverzicht!$O$2 -> 2025
B6: Contracturen : | C6: 38 | D6: Lokatie : | E6: SCHIJNDEL
B8: Datum | C8: Contracturen | D8: te laat | E8: Gewerkt | F8: Ziek | G8: Verlof | H8: Tandarts / Dokter
D9: ALLEEN 'x' invullen
B10: =DATE(G4,E4,1) -> 45748 | C10: =IFERROR(VLOOKUP(TEXT(WEEKDAY(B10),"dddd"),Afspraken!$A$4:$G$8,7,FALSE),"") -> 8.5 | D10: x | E10: 8.5
B11: =IF(MONTH(B10+1)<>$E$4,"",B10+1) -> 45749 | C11: =IFERROR(VLOOKUP(TEXT(WEEKDAY(B11),"dddd"),Afspraken!$A$4:$G$8,7,FALSE),"") -> 8.5 | E11: 8.5
B12: =IF(MONTH(B11+1)<>$E$4,"",B11+1) -> 45750 | C12: =IFERROR(VLOOKUP(TEXT(WEEKDAY(B12),"dddd"),Afspraken!$A$4:$G$8,7,FALSE),"") -> 8.5 | E12: 8.5
B13: =IF(MONTH(B12+1)<>$E$4,"",B12+1) -> 45751 | C13: =IFERROR(VLOOKUP(TEXT(WEEKDAY(B13),"dddd"),Afspraken!$A$4:$G$8,7,FALSE),"") -> 6 | E13: 6
B14: =IF(MONTH(B13+1)<>$E$4,"",B13+1) -> 45752 | C14: =IFERROR(VLOOKUP(TEXT(WEEKDAY(B14),"dddd"),Afspraken!$A$4:$G$8,7,FALSE),"")
B15: =IF(MONTH(B14+1)<>$E$4,"",B14+1) -> 45753 | C15: =IFERROR(VLOOKUP(TEXT(WEEKDAY(B15),"dddd"),Afspraken!$A$4:$G$8,7,FALSE),"")
B16: =IF(MONTH(B15+1)<>$E$4,"",B15+1) -> 45754 | C16: =IFERROR(VLOOKUP(TEXT(WEEKDAY(B16),"dddd"),Afspraken!$A$4:$G$8,7,FALSE),"") -> 8.5 | E16: 8.5
B17: =IF(MONTH(B16+1)<>$E$4,"",B16+1) -> 45755 | C17: =IFERROR(VLOOKUP(TEXT(WEEKDAY(B17),"dddd"),Afspraken!$A$4:$G$8,7,FALSE),"") -> 8.5 | E17: 8.5
B18: =IF(MONTH(B17+1)<>$E$4,"",B17+1) -> 45756 | C18: =IFERROR(VLOOKUP(TEXT(WEEKDAY(B18),"dddd"),Afspraken!$A$4:$G$8,7,FALSE),"") -> 8.5 | E18: 8.5
B19: =IF(MONTH(B18+1)<>$E$4,"",B18+1) -> 45757 | C19: =IFERROR(VLOOKUP(TEXT(WEEKDAY(B19),"dddd"),Afspraken!$A$4:$G$8,7,FALSE),"") -> 8.5 | E19: 8.5
B20: =IF(MONTH(B19+1)<>$E$4,"",B19+1) -> 45758 | C20: =IFERROR(VLOOKUP(TEXT(WEEKDAY(B20),"dddd"),Afspraken!$A$4:$G$8,7,FALSE),"") -> 6 | E20: 6
B21: =IF(MONTH(B20+1)<>$E$4,"",B20+1) -> 45759 | C21: =IFERROR(VLOOKUP(TEXT(WEEKDAY(B21),"dddd"),Afspraken!$A$4:$G$8,7,FALSE),"")
B22: =IF(MONTH(B21+1)<>$E$4,"",B21+1) -> 45760 | C22: =IFERROR(VLOOKUP(TEXT(WEEKDAY(B22),"dddd"),Afspraken!$A$4:$G$8,7,FALSE),"")
B23: =IF(MONTH(B22+1)<>$E$4,"",B22+1) -> 45761 | C23: =IFERROR(VLOOKUP(TEXT(WEEKDAY(B23),"dddd"),Afspraken!$A$4:$G$8,7,FALSE),"") -> 8.5 | E23: 9.5
B24: =IF(MONTH(B23+1)<>$E$4,"",B23+1) -> 45762 | C24: =IFERROR(VLOOKUP(TEXT(WEEKDAY(B24),"dddd"),Afspraken!$A$4:$G$8,7,FALSE),"") -> 8.5 | E24: 8.5
B25: =IF(MONTH(B24+1)<>$E$4,"",B24+1) -> 45763 | C25: =IFERROR(VLOOKUP(TEXT(WEEKDAY(B25),"dddd"),Afspraken!$A$4:$G$8,7,FALSE),"") -> 8.5 | E25: 8.5
B26: =IF(MONTH(B25+1)<>$E$4,"",B25+1) -> 45764 | C26: =IFERROR(VLOOKUP(TEXT(WEEKDAY(B26),"dddd"),Afspraken!$A$4:$G$8,7,FALSE),"") -> 8.5 | E26: 7.25
B27: =IF(MONTH(B26+1)<>$E$4,"",B26+1) -> 45765 | C27: =IFERROR(VLOOKUP(TEXT(WEEKDAY(B27),"dddd"),Afspraken!$A$4:$G$8,7,FALSE),"") -> 6 | E27: 6
B28: =IF(MONTH(B27+1)<>$E$4,"",B27+1) -> 45766 | C28: =IFERROR(VLOOKUP(TEXT(WEEKDAY(B28),"dddd"),Afspraken!$A$4:$G$8,7,FALSE),"")
B29: =IF(MONTH(B28+1)<>$E$4,"",B28+1) -> 45767 | C29: =IFERROR(VLOOKUP(TEXT(WEEKDAY(B29),"dddd"),Afspraken!$A$4:$G$8,7,FALSE),"")
B30: =IF(MONTH(B29+1)<>$E$4,"",B29+1) -> 45768 | C30: =IFERROR(VLOOKUP(TEXT(WEEKDAY(B30),"dddd"),Afspraken!$A$4:$G$8,7,FALSE),"") -> 8.5 | E30: 8.5
B31: =IF(MONTH(B30+1)<>$E$4,"",B30+1) -> 45769 | C31: =IFERROR(VLOOKUP(TEXT(WEEKDAY(B31),"dddd"),Afspraken!$A$4:$G$8,7,FALSE),"") -> 8.5 | G31: 8.5
B32: =IF(MONTH(B31+1)<>$E$4,"",B31+1) -> 45770 | C32: =IFERROR(VLOOKUP(TEXT(WEEKDAY(B32),"dddd"),Afspraken!$A$4:$G$8,7,FALSE),"") -> 8.5 | E32: 8.5
B33: =IF(MONTH(B32+1)<>$E$4,"",B32+1) -> 45771 | C33: =IFERROR(VLOOKUP(TEXT(WEEKDAY(B33),"dddd"),Afspraken!$A$4:$G$8,7,FALSE),"") -> 8.5 | E33: 8.5
B34: =IF(MONTH(B33+1)<>$E$4,"",B33+1) -> 45772 | C34: =IFERROR(VLOOKUP(TEXT(WEEKDAY(B34),"dddd"),Afspraken!$A$4:$G$8,7,FALSE),"") -> 6 | G34: 6
B35: =IF(MONTH(B34+1)<>$E$4,"",B34+1) -> 45773 | C35: =IFERROR(VLOOKUP(TEXT(WEEKDAY(B35),"dddd"),Afspraken!$A$4:$G$8,7,FALSE),"")
B36: =IF(MONTH(B35+1)<>$E$4,"",B35+1) -> 45774 | C36: =IFERROR(VLOOKUP(TEXT(WEEKDAY(B36),"dddd"),Afspraken!$A$4:$G$8,7,FALSE),"")
B37: =IF(MONTH(B36+1)<>$E$4,"",B36+1) -> 45775 | C37: =IFERROR(VLOOKUP(TEXT(WEEKDAY(B37),"dddd"),Afspraken!$A$4:$G$8,7,FALSE),"") -> 8.5 | E37: 9
B38: =IF(MONTH(B37+1)<>$E$4,"",B37+1) -> 45776 | C38: =IFERROR(VLOOKUP(TEXT(WEEKDAY(B38),"dddd"),Afspraken!$A$4:$G$8,7,FALSE),"") -> 8.5 | E38: 8.5
B39: =IF(MONTH(B37+2)<>$E$4,"",B37+2) -> 45777 | C39: =IFERROR(VLOOKUP(TEXT(WEEKDAY(B39),"dddd"),Afspraken!$A$4:$G$8,7,FALSE),"") -> 8.5 | E39: 8.5
B40: =IF(MONTH(B37+3)<>$E$4,"",B37+3) | C40: =IFERROR(VLOOKUP(TEXT(WEEKDAY(B40),"dddd"),Afspraken!$A$4:$G$8,7,FALSE),"")
B42: Totaal | C42: =SUM(C10:C40) -> 177 | D42: =SUM(D10:D41) -> 0 | E42: =SUM(E10:E41) -> 162.75 | F42: =SUM(F10:F41) -> 0 | G42: =SUM(G10:G41) -> 14.5 | H42: =SUM(H10:H41) -> 0

Sheet Periode 5
B2: Urenregistratie
B4: Naam : | C4: =IF(Verlofoverzicht!D2="","",Verlofoverzicht!D2) -> Maickel | D4: Periode : | E4: 5 | F4: Jaar : | G4: =Verlofoverzicht!$O$2 -> 2025
B6: Contracturen : | C6: 38 | D6: Lokatie : | E6: SCHIJNDEL
B8: Datum | C8: Contracturen | D8: te laat | E8: Gewerkt | F8: Ziek | G8: Verlof | H8: Tandarts / Dokter
D9: ALLEEN 'x' invullen
B10: =DATE(G4,E4,1) -> 45778 | C10: =IFERROR(VLOOKUP(TEXT(WEEKDAY(B10),"dddd"),Afspraken!$A$4:$G$8,7,FALSE),"") -> 8.5 | E10: 8.5
B11: =IF(MONTH(B10+1)<>$E$4,"",B10+1) -> 45779 | C11: =IFERROR(VLOOKUP(TEXT(WEEKDAY(B11),"dddd"),Afspraken!$A$4:$G$8,7,FALSE),"") -> 6 | E11: 6
B12: =IF(MONTH(B11+1)<>$E$4,"",B11+1) -> 45780 | C12: =IFERROR(VLOOKUP(TEXT(WEEKDAY(B12),"dddd"),Afspraken!$A$4:$G$8,7,FALSE),"")
B13: =IF(MONTH(B12+1)<>$E$4,"",B12+1) -> 45781 | C13: =IFERROR(VLOOKUP(TEXT(WEEKDAY(B13),"dddd"),Afspraken!$A$4:$G$8,7,FALSE),"")
B14: =IF(MONTH(B13+1)<>$E$4,"",B13+1) -> 45782 | C14: =IFERROR(VLOOKUP(TEXT(WEEKDAY(B14),"dddd"),Afspraken!$A$4:$G$8,7,FALSE),"") -> 8.5 | E14: 8.5
B15: =IF(MONTH(B14+1)<>$E$4,"",B14+1) -> 45783 | C15: =IFERROR(VLOOKUP(TEXT(WEEKDAY(B15),"dddd"),Afspraken!$A$4:$G$8,7,FALSE),"") -> 8.5 | E15: 7.25 | G15: 1.25
B16: =IF(MONTH(B15+1)<>$E$4,"",B15+1) -> 45784 | C16: =IFERROR(VLOOKUP(TEXT(WEEKDAY(B16),"dddd"),Afspraken!$A$4:$G$8,7,FALSE),"") -> 8.5 | E16: 4.75 | G16: 3.75
B17: =IF(MONTH(B16+1)<>$E$4,"",B16+1) -> 45785 | C17: =IFERROR(VLOOKUP(TEXT(WEEKDAY(B17),"dddd"),Afspraken!$A$4:$G$8,7,FALSE),"") -> 8.5 | E17: 8.5
B18: =IF(MONTH(B17+1)<>$E$4,"",B17+1) -> 45786 | C18: =IFERROR(VLOOKUP(TEXT(WEEKDAY(B18),"dddd"),Afspraken!$A$4:$G$8,7,FALSE),"") -> 6 | E18: 6
B19: =IF(MONTH(B18+1)<>$E$4,"",B18+1) -> 45787 | C19: =IFERROR(VLOOKUP(TEXT(WEEKDAY(B19),"dddd"),Afspraken!$A$4:$G$8,7,FALSE),"")
B20: =IF(MONTH(B19+1)<>$E$4,"",B19+1) -> 45788 | C20: =IFERROR(VLOOKUP(TEXT(WEEKDAY(B20),"dddd"),Afspraken!$A$4:$G$8,7,FALSE),"")
B21: =IF(MONTH(B20+1)<>$E$4,"",B20+1) -> 45789 | C21: =IFERROR(VLOOKUP(TEXT(WEEKDAY(B21),"dddd"),Afspraken!$A$4:$G$8,7,FALSE),"") -> 8.5 | E21: 5 | G21: 3.5
B22: =IF(MONTH(B21+1)<>$E$4,"",B21+1) -> 45790 | C22: =IFERROR(VLOOKUP(TEXT(WEEKDAY(B22),"dddd"),Afspraken!$A$4:$G$8,7,FALSE),"") -> 8.5 | E22: 8.5
B23: =IF(MONTH(B22+1)<>$E$4,"",B22+1) -> 45791 | C23: =IFERROR(VLOOKUP(TEXT(WEEKDAY(B23),"dddd"),Afspraken!$A$4:$G$8,7,FALSE),"") -> 8.5 | E23: 8.5
B24: =IF(MONTH(B23+1)<>$E$4,"",B23+1) -> 45792 | C24: =IFERROR(VLOOKUP(TEXT(WEEKDAY(B24),"dddd"),Afspraken!$A$4:$G$8,7,FALSE),"") -> 8.5 | E24: 8.5
B25: =IF(MONTH(B24+1)<>$E$4,"",B24+1) -> 45793 | C25: =IFERROR(VLOOKUP(TEXT(WEEKDAY(B25),"dddd"),Afspraken!$A$4:$G$8,7,FALSE),"") -> 6 | E25: 5.25 | G25: 0.75
B26: =IF(MONTH(B25+1)<>$E$4,"",B25+1) -> 45794 | C26: =IFERROR(VLOOKUP(TEXT(WEEKDAY(B26),"dddd"),Afspraken!$A$4:$G$8,7,FALSE),"")
B27: =IF(MONTH(B26+1)<>$E$4,"",B26+1) -> 45795 | C27: =IFERROR(VLOOKUP(TEXT(WEEKDAY(B27),"dddd"),Afspraken!$A$4:$G$8,7,FALSE),"")
B28: =IF(MONTH(B27+1)<>$E$4,"",B27+1) -> 45796 | C28: =IFERROR(VLOOKUP(TEXT(WEEKDAY(B28),"dddd"),Afspraken!$A$4:$G$8,7,FALSE),"") -> 8.5 | E28: 8.5
B29: =IF(MONTH(B28+1)<>$E$4,"",B28+1) -> 45797 | C29: =IFERROR(VLOOKUP(TEXT(WEEKDAY(B29),"dddd"),Afspraken!$A$4:$G$8,7,FALSE),"") -> 8.5 | E29: 8.5
B30: =IF(MONTH(B29+1)<>$E$4,"",B29+1) -> 45798 | C30: =IFERROR(VLOOKUP(TEXT(WEEKDAY(B30),"dddd"),Afspraken!$A$4:$G$8,7,FALSE),"") -> 8.5 | E30: 8.5
B31: =IF(MONTH(B30+1)<>$E$4,"",B30+1) -> 45799 | C31: =IFERROR(VLOOKUP(TEXT(WEEKDAY(B31),"dddd"),Afspraken!$A$4:$G$8,7,FALSE),"") -> 8.5 | E31: 8.5
B32: =IF(MONTH(B31+1)<>$E$4,"",B31+1) -> 45800 | C32: =IFERROR(VLOOKUP(TEXT(WEEKDAY(B32),"dddd"),Afspraken!$A$4:$G$8,7,FALSE),"") -> 6 | E32: 6
B33: =IF(MONTH(B32+1)<>$E$4,"",B32+1) -> 45801 | C33: =IFERROR(VLOOKUP(TEXT(WEEKDAY(B33),"dddd"),Afspraken!$A$4:$G$8,7,FALSE),"")
B34: =IF(MONTH(B33+1)<>$E$4,"",B33+1) -> 45802 | C34: =IFERROR(VLOOKUP(TEXT(WEEKDAY(B34),"dddd"),Afspraken!$A$4:$G$8,7,FALSE),"")
B35: =IF(MONTH(B34+1)<>$E$4,"",B34+1) -> 45803 | C35: =IFERROR(VLOOKUP(TEXT(WEEKDAY(B35),"dddd"),Afspraken!$A$4:$G$8,7,FALSE),"") -> 8.5 | E35: 8.5
B36: =IF(MONTH(B35+1)<>$E$4,"",B35+1) -> 45804 | C36: =IFERROR(VLOOKUP(TEXT(WEEKDAY(B36),"dddd"),Afspraken!$A$4:$G$8,7,FALSE),"") -> 8.5 | E36: 8.5
B37: =IF(MONTH(B36+1)<>$E$4,"",B36+1) -> 45805 | C37: =IFERROR(VLOOKUP(TEXT(WEEKDAY(B37),"dddd"),Afspraken!$A$4:$G$8,7,FALSE),"") -> 8.5 | E37: 8.5
B38: =IF(MONTH(B37+1)<>$E$4,"",B37+1) -> 45806 | C38: =IFERROR(VLOOKUP(TEXT(WEEKDAY(B38),"dddd"),Afspraken!$A$4:$G$8,7,FALSE),"") -> 8.5 | E38: 8.5
B39: =IF(MONTH(B37+2)<>$E$4,"",B37+2) -> 45807 | C39: =IFERROR(VLOOKUP(TEXT(WEEKDAY(B39),"dddd"),Afspraken!$A$4:$G$8,7,FALSE),"") -> 6 | G39: 6
B40: =IF(MONTH(B37+3)<>$E$4,"",B37+3) -> 45808 | C40: =IFERROR(VLOOKUP(TEXT(WEEKDAY(B40),"dddd"),Afspraken!$A$4:$G$8,7,FALSE),"")
B42: Totaal | C42: =SUM(C10:C40) -> 174.5 | D42: =SUM(D10:D40) -> 0 | E42: =SUM(E10:E40) -> 159.25 | F42: =SUM(F10:F40) -> 0 | G42: =SUM(G10:G40) -> 15.25 | H42: =SUM(H10:H40) -> 0

Sheet Periode 6
B2: Urenregistratie
B4: Naam : | C4: =IF(Verlofoverzicht!D2="","",Verlofoverzicht!D2) -> Maickel | D4: Periode : | E4: 6 | F4: Jaar : | G4: =Verlofoverzicht!$O$2 -> 2025
B6: Contracturen : | C6: 38 | D6: Lokatie : | E6: SCHIJNDEL
B8: Datum | C8: Contracturen | D8: te laat | E8: Gewerkt | F8: Ziek | G8: Verlof | H8: Tandarts / Dokter
D9: ALLEEN 'x' invullen
B10: =DATE(G4,E4,1) -> 45809 | C10: =IFERROR(VLOOKUP(TEXT(WEEKDAY(B10),"dddd"),Afspraken!$A$4:$G$8,7,FALSE),"")
B11: =IF(MONTH(B10+1)<>$E$4,"",B10+1) -> 45810 | C11: =IFERROR(VLOOKUP(TEXT(WEEKDAY(B11),"dddd"),Afspraken!$A$4:$G$8,7,FALSE),"") -> 8.5 | E11: 7.25 | G11: 1.25
B12: =IF(MONTH(B11+1)<>$E$4,"",B11+1) -> 45811 | C12: =IFERROR(VLOOKUP(TEXT(WEEKDAY(B12),"dddd"),Afspraken!$A$4:$G$8,7,FALSE),"") -> 8.5 | E12: 8.5
B13: =IF(MONTH(B12+1)<>$E$4,"",B12+1) -> 45812 | C13: =IFERROR(VLOOKUP(TEXT(WEEKDAY(B13),"dddd"),Afspraken!$A$4:$G$8,7,FALSE),"") -> 8.5 | E13: 7.25 | G13: 0.5
B14: =IF(MONTH(B13+1)<>$E$4,"",B13+1) -> 45813 | C14: =IFERROR(VLOOKUP(TEXT(WEEKDAY(B14),"dddd"),Afspraken!$A$4:$G$8,7,FALSE),"") -> 8.5 | E14: 8.5
B15: =IF(MONTH(B14+1)<>$E$4,"",B14+1) -> 45814 | C15: =IFERROR(VLOOKUP(TEXT(WEEKDAY(B15),"dddd"),Afspraken!$A$4:$G$8,7,FALSE),"") -> 6 | E15: 6.75
B16: =IF(MONTH(B15+1)<>$E$4,"",B15+1) -> 45815 | C16: =IFERROR(VLOOKUP(TEXT(WEEKDAY(B16),"dddd"),Afspraken!$A$4:$G$8,7,FALSE),"")
B17: =IF(MONTH(B16+1)<>$E$4,"",B16+1) -> 45816 | C17: =IFERROR(VLOOKUP(TEXT(WEEKDAY(B17),"dddd"),Afspraken!$A$4:$G$8,7,FALSE),"")
B18: =IF(MONTH(B17+1)<>$E$4,"",B17+1) -> 45817 | C18: =IFERROR(VLOOKUP(TEXT(WEEKDAY(B18),"dddd"),Afspraken!$A$4:$G$8,7,FALSE),"") -> 8.5 | E18: 8.5
B19: =IF(MONTH(B18+1)<>$E$4,"",B18+1) -> 45818 | C19: =IFERROR(VLOOKUP(TEXT(WEEKDAY(B19),"dddd"),Afspraken!$A$4:$G$8,7,FALSE),"") -> 8.5 | E19: 8.25
B20: =IF(MONTH(B19+1)<>$E$4,"",B19+1) -> 45819 | C20: =IFERROR(VLOOKUP(TEXT(WEEKDAY(B20),"dddd"),Afspraken!$A$4:$G$8,7,FALSE),"") -> 8.5 | E20: 8.5
B21: =IF(MONTH(B20+1)<>$E$4,"",B20+1) -> 45820 | C21: =IFERROR(VLOOKUP(TEXT(WEEKDAY(B21),"dddd"),Afspraken!$A$4:$G$8,7,FALSE),"") -> 8.5 | E21: 8.5
B22: =IF(MONTH(B21+1)<>$E$4,"",B21+1) -> 45821 | C22: =IFERROR(VLOOKUP(TEXT(WEEKDAY(B22),"dddd"),Afspraken!$A$4:$G$8,7,FALSE),"") -> 6 | E22: 6.5
B23: =IF(MONTH(B22+1)<>$E$4,"",B22+1) -> 45822 | C23: =IFERROR(VLOOKUP(TEXT(WEEKDAY(B23),"dddd"),Afspraken!$A$4:$G$8,7,FALSE),"")
B24: =IF(MONTH(B23+1)<>$E$4,"",B23+1) -> 45823 | C24: =IFERROR(VLOOKUP(TEXT(WEEKDAY(B24),"dddd"),Afspraken!$A$4:$G$8,7,FALSE),"")
B25: =IF(MONTH(B24+1)<>$E$4,"",B24+1) -> 45824 | C25: =IFERROR(VLOOKUP(TEXT(WEEKDAY(B25),"dddd"),Afspraken!$A$4:$G$8,7,FALSE),"") -> 8.5 | E25: 8.5
B26: =IF(MONTH(B25+1)<>$E$4,"",B25+1) -> 45825 | C26: =IFERROR(VLOOKUP(TEXT(WEEKDAY(B26),"dddd"),Afspraken!$A$4:$G$8,7,FALSE),"") -> 8.5 | E26: 8.5
B27: =IF(MONTH(B26+1)<>$E$4,"",B26+1) -> 45826 | C27: =IFERROR(VLOOKUP(TEXT(WEEKDAY(B27),"dddd"),Afspraken!$A$4:$G$8,7,FALSE),"") -> 8.5 | G27: 8.5
B28: =IF(MONTH(B27+1)<>$E$4,"",B27+1) -> 45827 | C28: =IFERROR(VLOOKUP(TEXT(WEEKDAY(B28),"dddd"),Afspraken!$A$4:$G$8,7,FALSE),"") -> 8.5 | G28: 8.5
B29: =IF(MONTH(B28+1)<>$E$4,"",B28+1) -> 45828 | C29: =IFERROR(VLOOKUP(TEXT(WEEKDAY(B29),"dddd"),Afspraken!$A$4:$G$8,7,FALSE),"") -> 6 | G29: 6
B30: =IF(MONTH(B29+1)<>$E$4,"",B29+1) -> 45829 | C30: =IFERROR(VLOOKUP(TEXT(WEEKDAY(B30),"dddd"),Afspraken!$A$4:$G$8,7,FALSE),"")
B31: =IF(MONTH(B30+1)<>$E$4,"",B30+1) -> 45830 | C31: =IFERROR(VLOOKUP(TEXT(WEEKDAY(B31),"dddd"),Afspraken!$A$4:$G$8,7,FALSE),"")
B32: =IF(MONTH(B31+1)<>$E$4,"",B31+1) -> 45831 | C32: =IFERROR(VLOOKUP(TEXT(WEEKDAY(B32),"dddd"),Afspraken!$A$4:$G$8,7,FALSE),"") -> 8.5 | G32: 8.5
B33: =IF(MONTH(B32+1)<>$E$4,"",B32+1) -> 45832 | C33: =IFERROR(VLOOKUP(TEXT(WEEKDAY(B33),"dddd"),Afspraken!$A$4:$G$8,7,FALSE),"") -> 8.5 | E33: 8.5
B34: =IF(MONTH(B33+1)<>$E$4,"",B33+1) -> 45833 | C34: =IFERROR(VLOOKUP(TEXT(WEEKDAY(B34),"dddd"),Afspraken!$A$4:$G$8,7,FALSE),"") -> 8.5 | E34: 7.25 | G34: 1.25
B35: =IF(MONTH(B34+1)<>$E$4,"",B34+1) -> 45834 | C35: =IFERROR(VLOOKUP(TEXT(WEEKDAY(B35),"dddd"),Afspraken!$A$4:$G$8,7,FALSE),"") -> 8.5 | E35: 8.5
B36: =IF(MONTH(B35+1)<>$E$4,"",B35+1) -> 45835 | C36: =IFERROR(VLOOKUP(TEXT(WEEKDAY(B36),"dddd"),Afspraken!$A$4:$G$8,7,FALSE),"") -> 6 | E36: 6
B37: =IF(MONTH(B36+1)<>$E$4,"",B36+1) -> 45836 | C37: =IFERROR(VLOOKUP(TEXT(WEEKDAY(B37),"dddd"),Afspraken!$A$4:$G$8,7,FALSE),"")
B38: =IF(MONTH(B37+1)<>$E$4,"",B37+1) -> 45837 | C38: =IFERROR(VLOOKUP(TEXT(WEEKDAY(B38),"dddd"),Afspraken!$A$4:$G$8,7,FALSE),"")
B39: =IF(MONTH(B37+2)<>$E$4,"",B37+2) -> 45838 | C39: =IFERROR(VLOOKUP(TEXT(WEEKDAY(B39),"dddd"),Afspraken!$A$4:$G$8,7,FALSE),"") -> 8.5 | E39: 8.5
B40: =IF(MONTH(B37+3)<>$E$4,"",B37+3) | C40: =IFERROR(VLOOKUP(TEXT(WEEKDAY(B40),"dddd"),Afspraken!$A$4:$G$8,7,FALSE),"")
B42: Totaal | C42: =SUM(C10:C40) -> 168.5 | D42: =SUM(D10:D40) -> 0 | E42: =SUM(E10:E40) -> 134.25 | F42: =SUM(F10:F40) -> 0 | G42: =SUM(G10:G40) -> 34.5 | H42: =SUM(H10:H40) -> 0

Sheet Periode 7
B2: Urenregistratie
B4: Naam : | C4: =IF(Verlofoverzicht!D2="","",Verlofoverzicht!D2) -> Maickel | D4: Periode : | E4: 7 | F4: Jaar : | G4: =Verlofoverzicht!$O$2 -> 2025
B6: Contracturen : | C6: 38 | D6: Lokatie : | E6: SCHIJNDEL
B8: Datum | C8: Contracturen | D8: te laat | E8: Gewerkt | F8: Ziek | G8: Verlof | H8: Tandarts / Dokter
D9: ALLEEN 'x' invullen
B10: =DATE(G4,E4,1) -> 45839 | C10: =IFERROR(VLOOKUP(TEXT(WEEKDAY(B10),"dddd"),Afspraken!$A$4:$G$8,7,FALSE),"") -> 8.5 | E10: 6.25
B11: =IF(MONTH(B10+1)<>$E$4,"",B10+1) -> 45840 | C11: =IFERROR(VLOOKUP(TEXT(WEEKDAY(B11),"dddd"),Afspraken!$A$4:$G$8,7,FALSE),"") -> 8.5 | E11: 8.5
B12: =IF(MONTH(B11+1)<>$E$4,"",B11+1) -> 45841 | C12: =IFERROR(VLOOKUP(TEXT(WEEKDAY(B12),"dddd"),Afspraken!$A$4:$G$8,7,FALSE),"") -> 8.5 | E12: 1.5 | G12: 7
B13: =IF(MONTH(B12+1)<>$E$4,"",B12+1) -> 45842 | C13: =IFERROR(VLOOKUP(TEXT(WEEKDAY(B13),"dddd"),Afspraken!$A$4:$G$8,7,FALSE),"") -> 6 | G13: 6
B14: =IF(MONTH(B13+1)<>$E$4,"",B13+1) -> 45843 | C14: =IFERROR(VLOOKUP(TEXT(WEEKDAY(B14),"dddd"),Afspraken!$A$4:$G$8,7,FALSE),"")
B15: =IF(MONTH(B14+1)<>$E$4,"",B14+1) -> 45844 | C15: =IFERROR(VLOOKUP(TEXT(WEEKDAY(B15),"dddd"),Afspraken!$A$4:$G$8,7,FALSE),"")
B16: =IF(MONTH(B15+1)<>$E$4,"",B15+1) -> 45845 | C16: =IFERROR(VLOOKUP(TEXT(WEEKDAY(B16),"dddd"),Afspraken!$A$4:$G$8,7,FALSE),"") -> 8.5 | D16: x | E16: 8.5
B17: =IF(MONTH(B16+1)<>$E$4,"",B16+1) -> 45846 | C17: =IFERROR(VLOOKUP(TEXT(WEEKDAY(B17),"dddd"),Afspraken!$A$4:$G$8,7,FALSE),"") -> 8.5 | E17: 8.5
B18: =IF(MONTH(B17+1)<>$E$4,"",B17+1) -> 45847 | C18: =IFERROR(VLOOKUP(TEXT(WEEKDAY(B18),"dddd"),Afspraken!$A$4:$G$8,7,FALSE),"") -> 8.5 | E18: 7.25
B19: =IF(MONTH(B18+1)<>$E$4,"",B18+1) -> 45848 | C19: =IFERROR(VLOOKUP(TEXT(WEEKDAY(B19),"dddd"),Afspraken!$A$4:$G$8,7,FALSE),"") -> 8.5 | E19: 13
B20: =IF(MONTH(B19+1)<>$E$4,"",B19+1) -> 45849 | C20: =IFERROR(VLOOKUP(TEXT(WEEKDAY(B20),"dddd"),Afspraken!$A$4:$G$8,7,FALSE),"") -> 6 | E20: 6
B21: =IF(MONTH(B20+1)<>$E$4,"",B20+1) -> 45850 | C21: =IFERROR(VLOOKUP(TEXT(WEEKDAY(B21),"dddd"),Afspraken!$A$4:$G$8,7,FALSE),"")
B22: =IF(MONTH(B21+1)<>$E$4,"",B21+1) -> 45851 | C22: =IFERROR(VLOOKUP(TEXT(WEEKDAY(B22),"dddd"),Afspraken!$A$4:$G$8,7,FALSE),"")
B23: =IF(MONTH(B22+1)<>$E$4,"",B22+1) -> 45852 | C23: =IFERROR(VLOOKUP(TEXT(WEEKDAY(B23),"dddd"),Afspraken!$A$4:$G$8,7,FALSE),"") -> 8.5 | E23: 8.5
B24: =IF(MONTH(B23+1)<>$E$4,"",B23+1) -> 45853 | C24: =IFERROR(VLOOKUP(TEXT(WEEKDAY(B24),"dddd"),Afspraken!$A$4:$G$8,7,FALSE),"") -> 8.5 | E24: 8.5
B25: =IF(MONTH(B24+1)<>$E$4,"",B24+1) -> 45854 | C25: =IFERROR(VLOOKUP(TEXT(WEEKDAY(B25),"dddd"),Afspraken!$A$4:$G$8,7,FALSE),"") -> 8.5 | E25: 8.5
B26: =IF(MONTH(B25+1)<>$E$4,"",B25+1) -> 45855 | C26: =IFERROR(VLOOKUP(TEXT(WEEKDAY(B26),"dddd"),Afspraken!$A$4:$G$8,7,FALSE),"") -> 8.5 | E26: 8.5
B27: =IF(MONTH(B26+1)<>$E$4,"",B26+1) -> 45856 | C27: =IFERROR(VLOOKUP(TEXT(WEEKDAY(B27),"dddd"),Afspraken!$A$4:$G$8,7,FALSE),"") -> 6 | E27: 6
B28: =IF(MONTH(B27+1)<>$E$4,"",B27+1) -> 45857 | C28: =IFERROR(VLOOKUP(TEXT(WEEKDAY(B28),"dddd"),Afspraken!$A$4:$G$8,7,FALSE),"")
B29: =IF(MONTH(B28+1)<>$E$4,"",B28+1) -> 45858 | C29: =IFERROR(VLOOKUP(TEXT(WEEKDAY(B29),"dddd"),Afspraken!$A$4:$G$8,7,FALSE),"")
B30: =IF(MONTH(B29+1)<>$E$4,"",B29+1) -> 45859 | C30: =IFERROR(VLOOKUP(TEXT(WEEKDAY(B30),"dddd"),Afspraken!$A$4:$G$8,7,FALSE),"") -> 8.5 | G30: 8.5
B31: =IF(MONTH(B30+1)<>$E$4,"",B30+1) -> 45860 | C31: =IFERROR(VLOOKUP(TEXT(WEEKDAY(B31),"dddd"),Afspraken!$A$4:$G$8,7,FALSE),"") -> 8.5 | G31: 8.5
B32: =IF(MONTH(B31+1)<>$E$4,"",B31+1) -> 45861 | C32: =IFERROR(VLOOKUP(TEXT(WEEKDAY(B32),"dddd"),Afspraken!$A$4:$G$8,7,FALSE),"") -> 8.5 | G32: 8.5
B33: =IF(MONTH(B32+1)<>$E$4,"",B32+1) -> 45862 | C33: =IFERROR(VLOOKUP(TEXT(WEEKDAY(B33),"dddd"),Afspraken!$A$4:$G$8,7,FALSE),"") -> 8.5 | G33: 8.5
B34: =IF(MONTH(B33+1)<>$E$4,"",B33+1) -> 45863 | C34: =IFERROR(VLOOKUP(TEXT(WEEKDAY(B34),"dddd"),Afspraken!$A$4:$G$8,7,FALSE),"") -> 6 | G34: 6
B35: =IF(MONTH(B34+1)<>$E$4,"",B34+1) -> 45864 | C35: =IFERROR(VLOOKUP(TEXT(WEEKDAY(B35),"dddd"),Afspraken!$A$4:$G$8,7,FALSE),"")
B36: =IF(MONTH(B35+1)<>$E$4,"",B35+1) -> 45865 | C36: =IFERROR(VLOOKUP(TEXT(WEEKDAY(B36),"dddd"),Afspraken!$A$4:$G$8,7,FALSE),"")
B37: =IF(MONTH(B36+1)<>$E$4,"",B36+1) -> 45866 | C37: =IFERROR(VLOOKUP(TEXT(WEEKDAY(B37),"dddd"),Afspraken!$A$4:$G$8,7,FALSE),"") -> 8.5 | G37: 8.5
B38: =IF(MONTH(B37+1)<>$E$4,"",B37+1) -> 45867 | C38: =IFERROR(VLOOKUP(TEXT(WEEKDAY(B38),"dddd"),Afspraken!$A$4:$G$8,7,FALSE),"") -> 8.5 | G38: 8.5
B39: =IF(MONTH(B37+2)<>$E$4,"",B37+2) -> 45868 | C39: =IFERROR(VLOOKUP(TEXT(WEEKDAY(B39),"dddd"),Afspraken!$A$4:$G$8,7,FALSE),"") -> 8.5 | G39: 8.5
B40: =IF(MONTH(B37+3)<>$E$4,"",B37+3) -> 45869 | C40: =IFERROR(VLOOKUP(TEXT(WEEKDAY(B40),"dddd"),Afspraken!$A$4:$G$8,7,FALSE),"") -> 8.5 | G40: 8.5
B42: Totaal | C42: =SUM(C10:C40) -> 185.5 | D42: 1 | E42: =SUM(E10:E40) -> 99.5 | F42: =SUM(F10:F40) -> 0 | G42: =SUM(G10:G40) -> 87 | H42: =SUM(H10:H40) -> 0

Sheet Periode 8
B2: Urenregistratie
B4: Naam : | C4: =IF(Verlofoverzicht!D2="","",Verlofoverzicht!D2) -> Maickel | D4: Periode : | E4: 8 | F4: Jaar : | G4: =Verlofoverzicht!$O$2 -> 2025
B6: Contracturen : | C6: 38 | D6: Lokatie : | E6: SCHIJNDEL
B8: Datum | C8: Contracturen | D8: te laat | E8: Gewerkt | F8: Ziek | G8: Verlof | H8: Tandarts / Dokter
D9: ALLEEN 'x' invullen
B10: =DATE(G4,E4,1) -> 45870 | C10: =IFERROR(VLOOKUP(TEXT(WEEKDAY(B10),"dddd"),Afspraken!$A$4:$G$8,7,FALSE),"") -> 6 | G10: 6
B11: =IF(MONTH(B10+1)<>$E$4,"",B10+1) -> 45871 | C11: =IFERROR(VLOOKUP(TEXT(WEEKDAY(B11),"dddd"),Afspraken!$A$4:$G$8,7,FALSE),"")
B12: =IF(MONTH(B11+1)<>$E$4,"",B11+1) -> 45872 | C12: =IFERROR(VLOOKUP(TEXT(WEEKDAY(B12),"dddd"),Afspraken!$A$4:$G$8,7,FALSE),"")
B13: =IF(MONTH(B12+1)<>$E$4,"",B12+1) -> 45873 | C13: =IFERROR(VLOOKUP(TEXT(WEEKDAY(B13),"dddd"),Afspraken!$A$4:$G$8,7,FALSE),"") -> 8.5 | G13: 8.5
B14: =IF(MONTH(B13+1)<>$E$4,"",B13+1) -> 45874 | C14: =IFERROR(VLOOKUP(TEXT(WEEKDAY(B14),"dddd"),Afspraken!$A$4:$G$8,7,FALSE),"") -> 8.5 | G14: 8.5
B15: =IF(MONTH(B14+1)<>$E$4,"",B14+1) -> 45875 | C15: =IFERROR(VLOOKUP(TEXT(WEEKDAY(B15),"dddd"),Afspraken!$A$4:$G$8,7,FALSE),"") -> 8.5 | G15: 8.5
B16: =IF(MONTH(B15+1)<>$E$4,"",B15+1) -> 45876 | C16: =IFERROR(VLOOKUP(TEXT(WEEKDAY(B16),"dddd"),Afspraken!$A$4:$G$8,7,FALSE),"") -> 8.5 | G16: 8.5
B17: =IF(MONTH(B16+1)<>$E$4,"",B16+1) -> 45877 | C17: =IFERROR(VLOOKUP(TEXT(WEEKDAY(B17),"dddd"),Afspraken!$A$4:$G$8,7,FALSE),"") -> 6 | G17: 6
B18: =IF(MONTH(B17+1)<>$E$4,"",B17+1) -> 45878 | C18: =IFERROR(VLOOKUP(TEXT(WEEKDAY(B18),"dddd"),Afspraken!$A$4:$G$8,7,FALSE),"")
B19: =IF(MONTH(B18+1)<>$E$4,"",B18+1) -> 45879 | C19: =IFERROR(VLOOKUP(TEXT(WEEKDAY(B19),"dddd"),Afspraken!$A$4:$G$8,7,FALSE),"")
B20: =IF(MONTH(B19+1)<>$E$4,"",B19+1) -> 45880 | C20: =IFERROR(VLOOKUP(TEXT(WEEKDAY(B20),"dddd"),Afspraken!$A$4:$G$8,7,FALSE),"") -> 8.5 | E20: 8.5
B21: =IF(MONTH(B20+1)<>$E$4,"",B20+1) -> 45881 | C21: =IFERROR(VLOOKUP(TEXT(WEEKDAY(B21),"dddd"),Afspraken!$A$4:$G$8,7,FALSE),"") -> 8.5 | E21: 7.25 | G21: 1.25
B22: =IF(MONTH(B21+1)<>$E$4,"",B21+1) -> 45882 | C22: =IFERROR(VLOOKUP(TEXT(WEEKDAY(B22),"dddd"),Afspraken!$A$4:$G$8,7,FALSE),"") -> 8.5 | E22: 8.5
B23: =IF(MONTH(B22+1)<>$E$4,"",B22+1) -> 45883 | C23: =IFERROR(VLOOKUP(TEXT(WEEKDAY(B23),"dddd"),Afspraken!$A$4:$G$8,7,FALSE),"") -> 8.5 | E23: 7.25 | G23: 1.25
B24: =IF(MONTH(B23+1)<>$E$4,"",B23+1) -> 45884 | C24: =IFERROR(VLOOKUP(TEXT(WEEKDAY(B24),"dddd"),Afspraken!$A$4:$G$8,7,FALSE),"") -> 6 | G24: 6
B25: =IF(MONTH(B24+1)<>$E$4,"",B24+1) -> 45885 | C25: =IFERROR(VLOOKUP(TEXT(WEEKDAY(B25),"dddd"),Afspraken!$A$4:$G$8,7,FALSE),"")
B26: =IF(MONTH(B25+1)<>$E$4,"",B25+1) -> 45886 | C26: =IFERROR(VLOOKUP(TEXT(WEEKDAY(B26),"dddd"),Afspraken!$A$4:$G$8,7,FALSE),"")
B27: =IF(MONTH(B26+1)<>$E$4,"",B26+1) -> 45887 | C27: =IFERROR(VLOOKUP(TEXT(WEEKDAY(B27),"dddd"),Afspraken!$A$4:$G$8,7,FALSE),"") -> 8.5 | D27: x | E27: 8.5
B28: =IF(MONTH(B27+1)<>$E$4,"",B27+1) -> 45888 | C28: =IFERROR(VLOOKUP(TEXT(WEEKDAY(B28),"dddd"),Afspraken!$A$4:$G$8,7,FALSE),"") -> 8.5 | D28: x | E28: 8.5
B29: =IF(MONTH(B28+1)<>$E$4,"",B28+1) -> 45889 | C29: =IFERROR(VLOOKUP(TEXT(WEEKDAY(B29),"dddd"),Afspraken!$A$4:$G$8,7,FALSE),"") -> 8.5 | E29: 6.5 | G29: 2
B30: =IF(MONTH(B29+1)<>$E$4,"",B29+1) -> 45890 | C30: =IFERROR(VLOOKUP(TEXT(WEEKDAY(B30),"dddd"),Afspraken!$A$4:$G$8,7,FALSE),"") -> 8.5 | E30: 8.5
B31: =IF(MONTH(B30+1)<>$E$4,"",B30+1) -> 45891 | C31: =IFERROR(VLOOKUP(TEXT(WEEKDAY(B31),"dddd"),Afspraken!$A$4:$G$8,7,FALSE),"") -> 6 | E31: 6
B32: =IF(MONTH(B31+1)<>$E$4,"",B31+1) -> 45892 | C32: =IFERROR(VLOOKUP(TEXT(WEEKDAY(B32),"dddd"),Afspraken!$A$4:$G$8,7,FALSE),"")
B33: =IF(MONTH(B32+1)<>$E$4,"",B32+1) -> 45893 | C33: =IFERROR(VLOOKUP(TEXT(WEEKDAY(B33),"dddd"),Afspraken!$A$4:$G$8,7,FALSE),"")
B34: =IF(MONTH(B33+1)<>$E$4,"",B33+1) -> 45894 | C34: =IFERROR(VLOOKUP(TEXT(WEEKDAY(B34),"dddd"),Afspraken!$A$4:$G$8,7,FALSE),"") -> 8.5 | E34: 7.25 | G34: 1.25
B35: =IF(MONTH(B34+1)<>$E$4,"",B34+1) -> 45895 | C35: =IFERROR(VLOOKUP(TEXT(WEEKDAY(B35),"dddd"),Afspraken!$A$4:$G$8,7,FALSE),"") -> 8.5 | E35: 7.75 | G35: 0.75
B36: =IF(MONTH(B35+1)<>$E$4,"",B35+1) -> 45896 | C36: =IFERROR(VLOOKUP(TEXT(WEEKDAY(B36),"dddd"),Afspraken!$A$4:$G$8,7,FALSE),"") -> 8.5 | E36: 8.5
B37: =IF(MONTH(B36+1)<>$E$4,"",B36+1) -> 45897 | C37: =IFERROR(VLOOKUP(TEXT(WEEKDAY(B37),"dddd"),Afspraken!$A$4:$G$8,7,FALSE),"") -> 8.5 | E37: 8.5
B38: =IF(MONTH(B37+1)<>$E$4,"",B37+1) -> 45898 | C38: =IFERROR(VLOOKUP(TEXT(WEEKDAY(B38),"dddd"),Afspraken!$A$4:$G$8,7,FALSE),"") -> 6 | E38: 6
B39: =IF(MONTH(B37+2)<>$E$4,"",B37+2) -> 45899 | C39: =IFERROR(VLOOKUP(TEXT(WEEKDAY(B39),"dddd"),Afspraken!$A$4:$G$8,7,FALSE),"")
B40: =IF(MONTH(B37+3)<>$E$4,"",B37+3) -> 45900 | C40: =IFERROR(VLOOKUP(TEXT(WEEKDAY(B40),"dddd"),Afspraken!$A$4:$G$8,7,FALSE),"")
B42: Totaal | C42: =SUM(C10:C40) -> 166 | D42: 2 | E42: =SUM(E10:E40) -> 107.5 | F42: =SUM(F10:F40) -> 0 | G42: =SUM(G10:G40) -> 58.5 | H42: =SUM(H10:H40) -> 0

Sheet Periode 9
B2: Urenregistratie
B4: Naam : | C4: =IF(Verlofoverzicht!D2="","",Verlofoverzicht!D2) -> Maickel | D4: Periode : | E4: 9 | F4: Jaar : | G4: =Verlofoverzicht!$O$2 -> 2025
B6: Contracturen : | C6: 38 | D6: Lokatie : | E6: SCHIJNDEL
B8: Datum | C8: Contracturen | D8: te laat | E8: Gewerkt | F8: Ziek | G8: Verlof | H8: Tandarts / Dokter
D9: ALLEEN 'x' invullen
B10: =DATE(G4,E4,1) -> 45901 | C10: =IFERROR(VLOOKUP(TEXT(WEEKDAY(B10),"dddd"),Afspraken!$A$4:$G$8,7,FALSE),"") -> 8.5 | E10: 8.5
B11: =IF(MONTH(B10+1)<>$E$4,"",B10+1) -> 45902 | C11: =IFERROR(VLOOKUP(TEXT(WEEKDAY(B11),"dddd"),Afspraken!$A$4:$G$8,7,FALSE),"") -> 8.5 | E11: 8.5
B12: =IF(MONTH(B11+1)<>$E$4,"",B11+1) -> 45903 | C12: =IFERROR(VLOOKUP(TEXT(WEEKDAY(B12),"dddd"),Afspraken!$A$4:$G$8,7,FALSE),"") -> 8.5 | E12: 8.5
B13: =IF(MONTH(B12+1)<>$E$4,"",B12+1) -> 45904 | C13: =IFERROR(VLOOKUP(TEXT(WEEKDAY(B13),"dddd"),Afspraken!$A$4:$G$8,7,FALSE),"") -> 8.5 | E13: 8.5
B14: =IF(MONTH(B13+1)<>$E$4,"",B13+1) -> 45905 | C14: =IFERROR(VLOOKUP(TEXT(WEEKDAY(B14),"dddd"),Afspraken!$A$4:$G$8,7,FALSE),"") -> 6 | G14: 6
B15: =IF(MONTH(B14+1)<>$E$4,"",B14+1) -> 45906 | C15: =IFERROR(VLOOKUP(TEXT(WEEKDAY(B15),"dddd"),Afspraken!$A$4:$G$8,7,FALSE),"")
B16: =IF(MONTH(B15+1)<>$E$4,"",B15+1) -> 45907 | C16: =IFERROR(VLOOKUP(TEXT(WEEKDAY(B16),"dddd"),Afspraken!$A$4:$G$8,7,FALSE),"")
B17: =IF(MONTH(B16+1)<>$E$4,"",B16+1) -> 45908 | C17: =IFERROR(VLOOKUP(TEXT(WEEKDAY(B17),"dddd"),Afspraken!$A$4:$G$8,7,FALSE),"") -> 8.5 | E17: 8.5
B18: =IF(MONTH(B17+1)<>$E$4,"",B17+1) -> 45909 | C18: =IFERROR(VLOOKUP(TEXT(WEEKDAY(B18),"dddd"),Afspraken!$A$4:$G$8,7,FALSE),"") -> 8.5 | E18: 8.5
B19: =IF(MONTH(B18+1)<>$E$4,"",B18+1) -> 45910 | C19: =IFERROR(VLOOKUP(TEXT(WEEKDAY(B19),"dddd"),Afspraken!$A$4:$G$8,7,FALSE),"") -> 8.5 | E19: 8.5
B20: =IF(MONTH(B19+1)<>$E$4,"",B19+1) -> 45911 | C20: =IFERROR(VLOOKUP(TEXT(WEEKDAY(B20),"dddd"),Afspraken!$A$4:$G$8,7,FALSE),"") -> 8.5 | E20: 8.5
B21: =IF(MONTH(B20+1)<>$E$4,"",B20+1) -> 45912 | C21: =IFERROR(VLOOKUP(TEXT(WEEKDAY(B21),"dddd"),Afspraken!$A$4:$G$8,7,FALSE),"") -> 6 | E21: 6
B22: =IF(MONTH(B21+1)<>$E$4,"",B21+1) -> 45913 | C22: =IFERROR(VLOOKUP(TEXT(WEEKDAY(B22),"dddd"),Afspraken!$A$4:$G$8,7,FALSE),"")
B23: =IF(MONTH(B22+1)<>$E$4,"",B22+1) -> 45914 | C23: =IFERROR(VLOOKUP(TEXT(WEEKDAY(B23),"dddd"),Afspraken!$A$4:$G$8,7,FALSE),"")
B24: =IF(MONTH(B23+1)<>$E$4,"",B23+1) -> 45915 | C24: =IFERROR(VLOOKUP(TEXT(WEEKDAY(B24),"dddd"),Afspraken!$A$4:$G$8,7,FALSE),"") -> 8.5 | E24: 8.5
B25: =IF(MONTH(B24+1)<>$E$4,"",B24+1) -> 45916 | C25: =IFERROR(VLOOKUP(TEXT(WEEKDAY(B25),"dddd"),Afspraken!$A$4:$G$8,7,FALSE),"") -> 8.5 | E25: 8.5
B26: =IF(MONTH(B25+1)<>$E$4,"",B25+1) -> 45917 | C26: =IFERROR(VLOOKUP(TEXT(WEEKDAY(B26),"dddd"),Afspraken!$A$4:$G$8,7,FALSE),"") -> 8.5 | E26: 8.5
B27: =IF(MONTH(B26+1)<>$E$4,"",B26+1) -> 45918 | C27: =IFERROR(VLOOKUP(TEXT(WEEKDAY(B27),"dddd"),Afspraken!$A$4:$G$8,7,FALSE),"") -> 8.5 | E27: 8.5
B28: =IF(MONTH(B27+1)<>$E$4,"",B27+1) -> 45919 | C28: =IFERROR(VLOOKUP(TEXT(WEEKDAY(B28),"dddd"),Afspraken!$A$4:$G$8,7,FALSE),"") -> 6 | E28: 6
B29: =IF(MONTH(B28+1)<>$E$4,"",B28+1) -> 45920 | C29: =IFERROR(VLOOKUP(TEXT(WEEKDAY(B29),"dddd"),Afspraken!$A$4:$G$8,7,FALSE),"")
B30: =IF(MONTH(B29+1)<>$E$4,"",B29+1) -> 45921 | C30: =IFERROR(VLOOKUP(TEXT(WEEKDAY(B30),"dddd"),Afspraken!$A$4:$G$8,7,FALSE),"")
B31: =IF(MONTH(B30+1)<>$E$4,"",B30+1) -> 45922 | C31: =IFERROR(VLOOKUP(TEXT(WEEKDAY(B31),"dddd"),Afspraken!$A$4:$G$8,7,FALSE),"") -> 8.5 | E31: 8.5
B32: =IF(MONTH(B31+1)<>$E$4,"",B31+1) -> 45923 | C32: =IFERROR(VLOOKUP(TEXT(WEEKDAY(B32),"dddd"),Afspraken!$A$4:$G$8,7,FALSE),"") -> 8.5 | E32: 8.5
B33: =IF(MONTH(B32+1)<>$E$4,"",B32+1) -> 45924 | C33: =IFERROR(VLOOKUP(TEXT(WEEKDAY(B33),"dddd"),Afspraken!$A$4:$G$8,7,FALSE),"") -> 8.5 | E33: 8.5
B34: =IF(MONTH(B33+1)<>$E$4,"",B33+1) -> 45925 | C34: =IFERROR(VLOOKUP(TEXT(WEEKDAY(B34),"dddd"),Afspraken!$A$4:$G$8,7,FALSE),"") -> 8.5 | E34: 8.5
B35: =IF(MONTH(B34+1)<>$E$4,"",B34+1) -> 45926 | C35: =IFERROR(VLOOKUP(TEXT(WEEKDAY(B35),"dddd"),Afspraken!$A$4:$G$8,7,FALSE),"") -> 6 | E35: 6
